Workbook

Sheet MarketplaceFees
A1: [MarketplaceFees Assumptions] | C1: Inputs used by the marketplace fee projection below.
A2: name | B2: value | C2: details
A3: projection_start_month | B3: 2026-03 | C3: First month of the synthetic projection in YYYY-MM format.
A4: seasonality_lookback_years | B4: 10 | C4: Historical lookback window used to build month-level seasonality factors.
A5: baseline_month | B5: 2026-03-01 | C5: Observed marketplace month used to anchor GMV and average selling price.
A6: baseline_month_gmv_usd | B6: 2165763 | C6: Observed GMV for the baseline month from raw daily sales data.
A7: baseline_month_transaction_count | B7: 514 | C7: Observed transaction count for the baseline month from raw daily sales data.
A8: baseline_month_avg_sell_price_usd | B8: 4213.55 | C8: Derived average selling price for the baseline month.
A9: sales_cagr | B9: 0.03 | C9: Annual growth rate applied to marketplace sales in Years 2 and 3.
A10: avg_sell_price_annual_growth | B10: 0.03 | C10: Annual inflation-style growth rate applied to average selling price.
A11: take_rate | B11: 0.02 | C11: Marketplace fee rate applied to projected GMV.
A12: year2_3_min_txns | B12: 10 | C12: Lower bound for projected monthly transaction count after Year 1.
A13: year2_3_max_txns | B13: 400 | C13: Upper bound for projected monthly transaction count after Year 1.
A14: jitter_std | B14: 0.05 | C14: Standard deviation used by the random-driver formulas.
A16: month | B16: year_index | C16: phase | D16: seasonality_factor | E16: noise_market_year1_jitter | F16: noise_market_txn | G16: noise_market_avg_sell_price | H16: cagr_multiplier | I16: noise_market_combined | J16: txn_trend_base | K16: txn_seasonality_multiplier | L16: transaction_count | M16: avg_sell_price_growth | N16: avg_sell_price_usd | O16: gross_market_value_usd | P16: take_rate | Q16: transaction_fee_revenue_usd
A17: 2026-03-01 | B17: 1 | C17: phase_1_user_growth | D17: 1 | E17: =MAX(0.7,1+_xlfn.NORM.INV(RAND(),0,$B$14*0.5)) -> 0.996398 | F17: =MAX(0.85,1+_xlfn.NORM.INV(RAND(),0,$B$14*0.4)) -> 1 | G17: =MAX(0.75,1+_xlfn.NORM.INV(RAND(),0,$B$14*0.35)) -> 1 | H17: =IF($B17=1,1,POWER(1+$B$9,-12/12)) -> 1 | I17: =IF($B17=1,E17,F17*G17) -> 0.996398 | J17: =IF($B17=1,0,$B$12+($B$13-$B$12)*(-12/23)) -> 0 | K17: =IF($B17=1,0,0.85+0.15*D17) -> 0 | L17: =IF($B17=1,0,MIN($B$13,MAX($B$12,ROUND(J17*K17*F17,0)))) -> 0 | M17: =IF($B17=1,0,1+($B$10*-12/12)) -> 0 | N17: =IF($B17=1,0,ROUND($B$8*M17*G17,2)) -> 0 | O17: =ROUND(L17*N17,2) -> 0 | P17: =$B$11 -> 0.02 | Q17: =ROUND(IF(L17>0,O17*P17,0),2) -> 0
A18: 2026-04-01 | B18: 1 | C18: phase_1_user_growth | D18: 0.98994723 | E18: =MAX(0.7,1+_xlfn.NORM.INV(RAND(),0,$B$14*0.5)) -> 0.995677 | F18: =MAX(0.85,1+_xlfn.NORM.INV(RAND(),0,$B$14*0.4)) -> 1 | G18: =MAX(0.75,1+_xlfn.NORM.INV(RAND(),0,$B$14*0.35)) -> 1 | H18: =IF($B18=1,1,POWER(1+$B$9,-11/12)) -> 1 | I18: =IF($B18=1,E18,F18*G18) -> 0.995677 | J18: =IF($B18=1,0,$B$12+($B$13-$B$12)*(-11/23)) -> 0 | K18: =IF($B18=1,0,0.85+0.15*D18) -> 0 | L18: =IF($B18=1,0,MIN($B$13,MAX($B$12,ROUND(J18*K18*F18,0)))) -> 0 | M18: =IF($B18=1,0,1+($B$10*-11/12)) -> 0 | N18: =IF($B18=1,0,ROUND($B$8*M18*G18,2)) -> 0 | O18: =ROUND(L18*N18,2) -> 0 | P18: =$B$11 -> 0.02 | Q18: =ROUND(IF(L18>0,O18*P18,0),2) -> 0
A19: 2026-05-01 | B19: 1 | C19: phase_1_user_growth | D19: 1.1889394 | E19: =MAX(0.7,1+_xlfn.NORM.INV(RAND(),0,$B$14*0.5)) -> 0.997217 | F19: =MAX(0.85,1+_xlfn.NORM.INV(RAND(),0,$B$14*0.4)) -> 1 | G19: =MAX(0.75,1+_xlfn.NORM.INV(RAND(),0,$B$14*0.35)) -> 1 | H19: =IF($B19=1,1,POWER(1+$B$9,-10/12)) -> 1 | I19: =IF($B19=1,E19,F19*G19) -> 0.997217 | J19: =IF($B19=1,0,$B$12+($B$13-$B$12)*(-10/23)) -> 0 | K19: =IF($B19=1,0,0.85+0.15*D19) -> 0 | L19: =IF($B19=1,0,MIN($B$13,MAX($B$12,ROUND(J19*K19*F19,0)))) -> 0 | M19: =IF($B19=1,0,1+($B$10*-10/12)) -> 0 | N19: =IF($B19=1,0,ROUND($B$8*M19*G19,2)) -> 0 | O19: =ROUND(L19*N19,2) -> 0 | P19: =$B$11 -> 0.02 | Q19: =ROUND(IF(L19>0,O19*P19,0),2) -> 0
A20: 2026-06-01 | B20: 1 | C20: phase_1_user_growth | D20: 1.0635797 | E20: =MAX(0.7,1+_xlfn.NORM.INV(RAND(),0,$B$14*0.5)) -> 1.01755 | F20: =MAX(0.85,1+_xlfn.NORM.INV(RAND(),0,$B$14*0.4)) -> 1 | G20: =MAX(0.75,1+_xlfn.NORM.INV(RAND(),0,$B$14*0.35)) -> 1 | H20: =IF($B20=1,1,POWER(1+$B$9,-9/12)) -> 1 | I20: =IF($B20=1,E20,F20*G20) -> 1.01755 | J20: =IF($B20=1,0,$B$12+($B$13-$B$12)*(-9/23)) -> 0 | K20: =IF($B20=1,0,0.85+0.15*D20) -> 0 | L20: =IF($B20=1,0,MIN($B$13,MAX($B$12,ROUND(J20*K20*F20,0)))) -> 0 | M20: =IF($B20=1,0,1+($B$10*-9/12)) -> 0 | N20: =IF($B20=1,0,ROUND($B$8*M20*G20,2)) -> 0 | O20: =ROUND(L20*N20,2) -> 0 | P20: =$B$11 -> 0.02 | Q20: =ROUND(IF(L20>0,O20*P20,0),2) -> 0
A21: 2026-07-01 | B21: 1 | C21: phase_1_user_growth | D21: 1.0466681 | E21: =MAX(0.7,1+_xlfn.NORM.INV(RAND(),0,$B$14*0.5)) -> 0.99681 | F21: =MAX(0.85,1+_xlfn.NORM.INV(RAND(),0,$B$14*0.4)) -> 1 | G21: =MAX(0.75,1+_xlfn.NORM.INV(RAND(),0,$B$14*0.35)) -> 1 | H21: =IF($B21=1,1,POWER(1+$B$9,-8/12)) -> 1 | I21: =IF($B21=1,E21,F21*G21) -> 0.99681 | J21: =IF($B21=1,0,$B$12+($B$13-$B$12)*(-8/23)) -> 0 | K21: =IF($B21=1,0,0.85+0.15*D21) -> 0 | L21: =IF($B21=1,0,MIN($B$13,MAX($B$12,ROUND(J21*K21*F21,0)))) -> 0 | M21: =IF($B21=1,0,1+($B$10*-8/12)) -> 0 | N21: =IF($B21=1,0,ROUND($B$8*M21*G21,2)) -> 0 | O21: =ROUND(L21*N21,2) -> 0 | P21: =$B$11 -> 0.02 | Q21: =ROUND(IF(L21>0,O21*P21,0),2) -> 0
A22: 2026-08-01 | B22: 1 | C22: phase_1_user_growth | D22: 1.0816408 | E22: =MAX(0.7,1+_xlfn.NORM.INV(RAND(),0,$B$14*0.5)) -> 0.962566 | F22: =MAX(0.85,1+_xlfn.NORM.INV(RAND(),0,$B$14*0.4)) -> 1 | G22: =MAX(0.75,1+_xlfn.NORM.INV(RAND(),0,$B$14*0.35)) -> 1 | H22: =IF($B22=1,1,POWER(1+$B$9,-7/12)) -> 1 | I22: =IF($B22=1,E22,F22*G22) -> 0.962566 | J22: =IF($B22=1,0,$B$12+($B$13-$B$12)*(-7/23)) -> 0 | K22: =IF($B22=1,0,0.85+0.15*D22) -> 0 | L22: =IF($B22=1,0,MIN($B$13,MAX($B$12,ROUND(J22*K22*F22,0)))) -> 0 | M22: =IF($B22=1,0,1+($B$10*-7/12)) -> 0 | N22: =IF($B22=1,0,ROUND($B$8*M22*G22,2)) -> 0 | O22: =ROUND(L22*N22,2) -> 0 | P22: =$B$11 -> 0.02 | Q22: =ROUND(IF(L22>0,O22*P22,0),2) -> 0
A23: 2026-09-01 | B23: 1 | C23: phase_1_user_growth | D23: 1.0397956 | E23: =MAX(0.7,1+_xlfn.NORM.INV(RAND(),0,$B$14*0.5)) -> 1.008308 | F23: =MAX(0.85,1+_xlfn.NORM.INV(RAND(),0,$B$14*0.4)) -> 1 | G23: =MAX(0.75,1+_xlfn.NORM.INV(RAND(),0,$B$14*0.35)) -> 1 | H23: =IF($B23=1,1,POWER(1+$B$9,-6/12)) -> 1 | I23: =IF($B23=1,E23,F23*G23) -> 1.008308 | J23: =IF($B23=1,0,$B$12+($B$13-$B$12)*(-6/23)) -> 0 | K23: =IF($B23=1,0,0.85+0.15*D23) -> 0 | L23: =IF($B23=1,0,MIN($B$13,MAX($B$12,ROUND(J23*K23*F23,0)))) -> 0 | M23: =IF($B23=1,0,1+($B$10*-6/12)) -> 0 | N23: =IF($B23=1,0,ROUND($B$8*M23*G23,2)) -> 0 | O23: =ROUND(L23*N23,2) -> 0 | P23: =$B$11 -> 0.02 | Q23: =ROUND(IF(L23>0,O23*P23,0),2) -> 0
A24: 2026-10-01 | B24: 1 | C24: phase_1_user_growth | D24: 1.0691942 | E24: =MAX(0.7,1+_xlfn.NORM.INV(RAND(),0,$B$14*0.5)) -> 0.993317 | F24: =MAX(0.85,1+_xlfn.NORM.INV(RAND(),0,$B$14*0.4)) -> 1 | G24: =MAX(0.75,1+_xlfn.NORM.INV(RAND(),0,$B$14*0.35)) -> 1 | H24: =IF($B24=1,1,POWER(1+$B$9,-5/12)) -> 1 | I24: =IF($B24=1,E24,F24*G24) -> 0.993317 | J24: =IF($B24=1,0,$B$12+($B$13-$B$12)*(-5/23)) -> 0 | K24: =IF($B24=1,0,0.85+0.15*D24) -> 0 | L24: =IF($B24=1,0,MIN($B$13,MAX($B$12,ROUND(J24*K24*F24,0)))) -> 0 | M24: =IF($B24=1,0,1+($B$10*-5/12)) -> 0 | N24: =IF($B24=1,0,ROUND($B$8*M24*G24,2)) -> 0 | O24: =ROUND(L24*N24,2) -> 0 | P24: =$B$11 -> 0.02 | Q24: =ROUND(IF(L24>0,O24*P24,0),2) -> 0
A25: 2026-11-01 | B25: 1 | C25: phase_1_user_growth | D25: 1.213324 | E25: =MAX(0.7,1+_xlfn.NORM.INV(RAND(),0,$B$14*0.5)) -> 0.994576 | F25: =MAX(0.85,1+_xlfn.NORM.INV(RAND(),0,$B$14*0.4)) -> 1 | G25: =MAX(0.75,1+_xlfn.NORM.INV(RAND(),0,$B$14*0.35)) -> 1 | H25: =IF($B25=1,1,POWER(1+$B$9,-4/12)) -> 1 | I25: =IF($B25=1,E25,F25*G25) -> 0.994576 | J25: =IF($B25=1,0,$B$12+($B$13-$B$12)*(-4/23)) -> 0 | K25: =IF($B25=1,0,0.85+0.15*D25) -> 0 | L25: =IF($B25=1,0,MIN($B$13,MAX($B$12,ROUND(J25*K25*F25,0)))) -> 0 | M25: =IF($B25=1,0,1+($B$10*-4/12)) -> 0 | N25: =IF($B25=1,0,ROUND($B$8*M25*G25,2)) -> 0 | O25: =ROUND(L25*N25,2) -> 0 | P25: =$B$11 -> 0.02 | Q25: =ROUND(IF(L25>0,O25*P25,0),2) -> 0
A26: 2026-12-01 | B26: 1 | C26: phase_1_user_growth | D26: 2.2762742 | E26: =MAX(0.7,1+_xlfn.NORM.INV(RAND(),0,$B$14*0.5)) -> 1.002897 | F26: =MAX(0.85,1+_xlfn.NORM.INV(RAND(),0,$B$14*0.4)) -> 1 | G26: =MAX(0.75,1+_xlfn.NORM.INV(RAND(),0,$B$14*0.35)) -> 1 | H26: =IF($B26=1,1,POWER(1+$B$9,-3/12)) -> 1 | I26: =IF($B26=1,E26,F26*G26) -> 1.002897 | J26: =IF($B26=1,0,$B$12+($B$13-$B$12)*(-3/23)) -> 0 | K26: =IF($B26=1,0,0.85+0.15*D26) -> 0 | L26: =IF($B26=1,0,MIN($B$13,MAX($B$12,ROUND(J26*K26*F26,0)))) -> 0 | M26: =IF($B26=1,0,1+($B$10*-3/12)) -> 0 | N26: =IF($B26=1,0,ROUND($B$8*M26*G26,2)) -> 0 | O26: =ROUND(L26*N26,2) -> 0 | P26: =$B$11 -> 0.02 | Q26: =ROUND(IF(L26>0,O26*P26,0),2) -> 0
A27: 2027-01-01 | B27: 1 | C27: phase_1_user_growth | D27: 0.94587711 | E27: =MAX(0.7,1+_xlfn.NORM.INV(RAND(),0,$B$14*0.5)) -> 1.005807 | F27: =MAX(0.85,1+_xlfn.NORM.INV(RAND(),0,$B$14*0.4)) -> 1 | G27: =MAX(0.75,1+_xlfn.NORM.INV(RAND(),0,$B$14*0.35)) -> 1 | H27: =IF($B27=1,1,POWER(1+$B$9,-2/12)) -> 1 | I27: =IF($B27=1,E27,F27*G27) -> 1.005807 | J27: =IF($B27=1,0,$B$12+($B$13-$B$12)*(-2/23)) -> 0 | K27: =IF($B27=1,0,0.85+0.15*D27) -> 0 | L27: =IF($B27=1,0,MIN($B$13,MAX($B$12,ROUND(J27*K27*F27,0)))) -> 0 | M27: =IF($B27=1,0,1+($B$10*-2/12)) -> 0 | N27: =IF($B27=1,0,ROUND($B$8*M27*G27,2)) -> 0 | O27: =ROUND(L27*N27,2) -> 0 | P27: =$B$11 -> 0.02 | Q27: =ROUND(IF(L27>0,O27*P27,0),2) -> 0
A28: 2027-02-01 | B28: 1 | C28: phase_1_user_growth | D28: 1.167967 | E28: =MAX(0.7,1+_xlfn.NORM.INV(RAND(),0,$B$14*0.5)) -> 1.029089 | F28: =MAX(0.85,1+_xlfn.NORM.INV(RAND(),0,$B$14*0.4)) -> 1 | G28: =MAX(0.75,1+_xlfn.NORM.INV(RAND(),0,$B$14*0.35)) -> 1 | H28: =IF($B28=1,1,POWER(1+$B$9,-1/12)) -> 1 | I28: =IF($B28=1,E28,F28*G28) -> 1.029089 | J28: =IF($B28=1,0,$B$12+($B$13-$B$12)*(-1/23)) -> 0 | K28: =IF($B28=1,0,0.85+0.15*D28) -> 0 | L28: =IF($B28=1,0,MIN($B$13,MAX($B$12,ROUND(J28*K28*F28,0)))) -> 0 | M28: =IF($B28=1,0,1+($B$10*-1/12)) -> 0 | N28: =IF($B28=1,0,ROUND($B$8*M28*G28,2)) -> 0 | O28: =ROUND(L28*N28,2) -> 0 | P28: =$B$11 -> 0.02 | Q28: =ROUND(IF(L28>0,O28*P28,0),2) -> 0
A29: 2027-03-01 | B29: 2 | C29: phase_2_marketplace_activation | D29: 1 | E29: =MAX(0.7,1+_xlfn.NORM.INV(RAND(),0,$B$14*0.5)) -> 1 | F29: =MAX(0.85,1+_xlfn.NORM.INV(RAND(),0,$B$14*0.4)) -> 1.013133 | G29: =MAX(0.75,1+_xlfn.NORM.INV(RAND(),0,$B$14*0.35)) -> 1.001934 | H29: =IF($B29=1,1,POWER(1+$B$9,0/12)) -> 1 | I29: =IF($B29=1,E29,F29*G29) -> 1.015092 | J29: =IF($B29=1,0,$B$12+($B$13-$B$12)*(0/23)) -> 10 | K29: =IF($B29=1,0,0.85+0.15*D29) -> 1 | L29: =IF($B29=1,0,MIN($B$13,MAX($B$12,ROUND(J29*K29*F29,0)))) -> 10 | M29: =IF($B29=1,0,1+($B$10*0/12)) -> 1 | N29: =IF($B29=1,0,ROUND($B$8*M29*G29,2)) -> 4221.7 | O29: =ROUND(L29*N29,2) -> 42216.95 | P29: =$B$11 -> 0.02 | Q29: =ROUND(IF(L29>0,O29*P29,0),2) -> 844.34
A30: 2027-04-01 | B30: 2 | C30: phase_2_marketplace_activation | D30: 0.98994723 | E30: =MAX(0.7,1+_xlfn.NORM.INV(RAND(),0,$B$14*0.5)) -> 1 | F30: =MAX(0.85,1+_xlfn.NORM.INV(RAND(),0,$B$14*0.4)) -> 0.985234 | G30: =MAX(0.75,1+_xlfn.NORM.INV(RAND(),0,$B$14*0.35)) -> 0.982243 | H30: =IF($B30=1,1,POWER(1+$B$9,1/12)) -> 1.002466 | I30: =IF($B30=1,E30,F30*G30) -> 0.967739 | J30: =IF($B30=1,0,$B$12+($B$13-$B$12)*(1/23)) -> 26.956522 | K30: =IF($B30=1,0,0.85+0.15*D30) -> 0.99849208 | L30: =IF($B30=1,0,MIN($B$13,MAX($B$12,ROUND(J30*K30*F30,0)))) -> 27 | M30: =IF($B30=1,0,1+($B$10*1/12)) -> 1.0025 | N30: =IF($B30=1,0,ROUND($B$8*M30*G30,2)) -> 4149.08 | O30: =ROUND(L30*N30,2) -> 112025.03 | P30: =$B$11 -> 0.02 | Q30: =ROUND(IF(L30>0,O30*P30,0),2) -> 2240.5
A31: 2027-05-01 | B31: 2 | C31: phase_2_marketplace_activation | D31: 1.1889394 | E31: =MAX(0.7,1+_xlfn.NORM.INV(RAND(),0,$B$14*0.5)) -> 1 | F31: =MAX(0.85,1+_xlfn.NORM.INV(RAND(),0,$B$14*0.4)) -> 1.004927 | G31: =MAX(0.75,1+_xlfn.NORM.INV(RAND(),0,$B$14*0.35)) -> 1.022944 | H31: =IF($B31=1,1,POWER(1+$B$9,2/12)) -> 1.004939 | I31: =IF($B31=1,E31,F31*G31) -> 1.027984 | J31: =IF($B31=1,0,$B$12+($B$13-$B$12)*(2/23)) -> 43.913043 | K31: =IF($B31=1,0,0.85+0.15*D31) -> 1.0283409 | L31: =IF($B31=1,0,MIN($B$13,MAX($B$12,ROUND(J31*K31*F31,0)))) -> 45 | M31: =IF($B31=1,0,1+($B$10*2/12)) -> 1.005 | N31: =IF($B31=1,0,ROUND($B$8*M31*G31,2)) -> 4331.77 | O31: =ROUND(L31*N31,2) -> 194929.79 | P31: =$B$11 -> 0.02 | Q31: =ROUND(IF(L31>0,O31*P31,0),2) -> 3898.6
A32: 2027-06-01 | B32: 2 | C32: phase_2_marketplace_activation | D32: 1.0635797 | E32: =MAX(0.7,1+_xlfn.NORM.INV(RAND(),0,$B$14*0.5)) -> 1 | F32: =MAX(0.85,1+_xlfn.NORM.INV(RAND(),0,$B$14*0.4)) -> 1.000833 | G32: =MAX(0.75,1+_xlfn.NORM.INV(RAND(),0,$B$14*0.35)) -> 0.998139 | H32: =IF($B32=1,1,POWER(1+$B$9,3/12)) -> 1.007417 | I32: =IF($B32=1,E32,F32*G32) -> 0.998971 | J32: =IF($B32=1,0,$B$12+($B$13-$B$12)*(3/23)) -> 60.869565 | K32: =IF($B32=1,0,0.85+0.15*D32) -> 1.009537 | L32: =IF($B32=1,0,MIN($B$13,MAX($B$12,ROUND(J32*K32*F32,0)))) -> 62 | M32: =IF($B32=1,0,1+($B$10*3/12)) -> 1.0075 | N32: =IF($B32=1,0,ROUND($B$8*M32*G32,2)) -> 4237.25 | O32: =ROUND(L32*N32,2) -> 262709.47 | P32: =$B$11 -> 0.02 | Q32: =ROUND(IF(L32>0,O32*P32,0),2) -> 5254.19
A33: 2027-07-01 | B33: 2 | C33: phase_2_marketplace_activation | D33: 1.0466681 | E33: =MAX(0.7,1+_xlfn.NORM.INV(RAND(),0,$B$14*0.5)) -> 1 | F33: =MAX(0.85,1+_xlfn.NORM.INV(RAND(),0,$B$14*0.4)) -> 1.010636 | G33: =MAX(0.75,1+_xlfn.NORM.INV(RAND(),0,$B$14*0.35)) -> 0.974563 | H33: =IF($B33=1,1,POWER(1+$B$9,4/12)) -> 1.009902 | I33: =IF($B33=1,E33,F33*G33) -> 0.984928 | J33: =IF($B33=1,0,$B$12+($B$13-$B$12)*(4/23)) -> 77.826087 | K33: =IF($B33=1,0,0.85+0.15*D33) -> 1.0070002 | L33: =IF($B33=1,0,MIN($B$13,MAX($B$12,ROUND(J33*K33*F33,0)))) -> 79 | M33: =IF($B33=1,0,1+($B$10*4/12)) -> 1.01 | N33: =IF($B33=1,0,ROUND($B$8*M33*G33,2)) -> 4147.43 | O33: =ROUND(L33*N33,2) -> 327646.99 | P33: =$B$11 -> 0.02 | Q33: =ROUND(IF(L33>0,O33*P33,0),2) -> 6552.94
A34: 2027-08-01 | B34: 2 | C34: phase_2_marketplace_activation | D34: 1.0816408 | E34: =MAX(0.7,1+_xlfn.NORM.INV(RAND(),0,$B$14*0.5)) -> 1 | F34: =MAX(0.85,1+_xlfn.NORM.INV(RAND(),0,$B$14*0.4)) -> 0.993754 | G34: =MAX(0.75,1+_xlfn.NORM.INV(RAND(),0,$B$14*0.35)) -> 1.008581 | H34: =IF($B34=1,1,POWER(1+$B$9,5/12)) -> 1.012392 | I34: =IF($B34=1,E34,F34*G34) -> 1.002282 | J34: =IF($B34=1,0,$B$12+($B$13-$B$12)*(5/23)) -> 94.782609 | K34: =IF($B34=1,0,0.85+0.15*D34) -> 1.0122461 | L34: =IF($B34=1,0,MIN($B$13,MAX($B$12,ROUND(J34*K34*F34,0)))) -> 95 | M34: =IF($B34=1,0,1+($B$10*5/12)) -> 1.0125 | N34: =IF($B34=1,0,ROUND($B$8*M34*G34,2)) -> 4302.83 | O34: =ROUND(L34*N34,2) -> 408768.46 | P34: =$B$11 -> 0.02 | Q34: =ROUND(IF(L34>0,O34*P34,0),2) -> 8175.37
A35: 2027-09-01 | B35: 2 | C35: phase_2_marketplace_activation | D35: 1.0397956 | E35: =MAX(0.7,1+_xlfn.NORM.INV(RAND(),0,$B$14*0.5)) -> 1 | F35: =MAX(0.85,1+_xlfn.NORM.INV(RAND(),0,$B$14*0.4)) -> 1.017468 | G35: =MAX(0.75,1+_xlfn.NORM.INV(RAND(),0,$B$14*0.35)) -> 0.995789 | H35: =IF($B35=1,1,POWER(1+$B$9,6/12)) -> 1.014889 | I35: =IF($B35=1,E35,F35*G35) -> 1.013184 | J35: =IF($B35=1,0,$B$12+($B$13-$B$12)*(6/23)) -> 111.73913 | K35: =IF($B35=1,0,0.85+0.15*D35) -> 1.0059693 | L35: =IF($B35=1,0,MIN($B$13,MAX($B$12,ROUND(J35*K35*F35,0)))) -> 114 | M35: =IF($B35=1,0,1+($B$10*6/12)) -> 1.015 | N35: =IF($B35=1,0,ROUND($B$8*M35*G35,2)) -> 4258.74 | O35: =ROUND(L35*N35,2) -> 485496.41 | P35: =$B$11 -> 0.02 | Q35: =ROUND(IF(L35>0,O35*P35,0),2) -> 9709.93
A36: 2027-10-01 | B36: 2 | C36: phase_2_marketplace_activation | D36: 1.0691942 | E36: =MAX(0.7,1+_xlfn.NORM.INV(RAND(),0,$B$14*0.5)) -> 1 | F36: =MAX(0.85,1+_xlfn.NORM.INV(RAND(),0,$B$14*0.4)) -> 1.007532 | G36: =MAX(0.75,1+_xlfn.NORM.INV(RAND(),0,$B$14*0.35)) -> 1.004344 | H36: =IF($B36=1,1,POWER(1+$B$9,7/12)) -> 1.017392 | I36: =IF($B36=1,E36,F36*G36) -> 1.011908 | J36: =IF($B36=1,0,$B$12+($B$13-$B$12)*(7/23)) -> 128.69565 | K36: =IF($B36=1,0,0.85+0.15*D36) -> 1.0103791 | L36: =IF($B36=1,0,MIN($B$13,MAX($B$12,ROUND(J36*K36*F36,0)))) -> 131 | M36: =IF($B36=1,0,1+($B$10*7/12)) -> 1.0175 | N36: =IF($B36=1,0,ROUND($B$8*M36*G36,2)) -> 4305.91 | O36: =ROUND(L36*N36,2) -> 564073.76 | P36: =$B$11 -> 0.02 | Q36: =ROUND(IF(L36>0,O36*P36,0),2) -> 11281.48
A37: 2027-11-01 | B37: 2 | C37: phase_2_marketplace_activation | D37: 1.213324 | E37: =MAX(0.7,1+_xlfn.NORM.INV(RAND(),0,$B$14*0.5)) -> 1 | F37: =MAX(0.85,1+_xlfn.NORM.INV(RAND(),0,$B$14*0.4)) -> 1.015647 | G37: =MAX(0.75,1+_xlfn.NORM.INV(RAND(),0,$B$14*0.35)) -> 0.980519 | H37: =IF($B37=1,1,POWER(1+$B$9,8/12)) -> 1.019901 | I37: =IF($B37=1,E37,F37*G37) -> 0.99586 | J37: =IF($B37=1,0,$B$12+($B$13-$B$12)*(8/23)) -> 145.65217 | K37: =IF($B37=1,0,0.85+0.15*D37) -> 1.0319986 | L37: =IF($B37=1,0,MIN($B$13,MAX($B$12,ROUND(J37*K37*F37,0)))) -> 153 | M37: =IF($B37=1,0,1+($B$10*8/12)) -> 1.02 | N37: =IF($B37=1,0,ROUND($B$8*M37*G37,2)) -> 4214.09 | O37: =ROUND(L37*N37,2) -> 644755.8 | P37: =$B$11 -> 0.02 | Q37: =ROUND(IF(L37>0,O37*P37,0),2) -> 12895.12
A38: 2027-12-01 | B38: 2 | C38: phase_2_marketplace_activation | D38: 2.2762742 | E38: =MAX(0.7,1+_xlfn.NORM.INV(RAND(),0,$B$14*0.5)) -> 1 | F38: =MAX(0.85,1+_xlfn.NORM.INV(RAND(),0,$B$14*0.4)) -> 1.011365 | G38: =MAX(0.75,1+_xlfn.NORM.INV(RAND(),0,$B$14*0.35)) -> 0.973496 | H38: =IF($B38=1,1,POWER(1+$B$9,9/12)) -> 1.022417 | I38: =IF($B38=1,E38,F38*G38) -> 0.98456 | J38: =IF($B38=1,0,$B$12+($B$13-$B$12)*(9/23)) -> 162.6087 | K38: =IF($B38=1,0,0.85+0.15*D38) -> 1.1914411 | L38: =IF($B38=1,0,MIN($B$13,MAX($B$12,ROUND(J38*K38*F38,0)))) -> 196 | M38: =IF($B38=1,0,1+($B$10*9/12)) -> 1.0225 | N38: =IF($B38=1,0,ROUND($B$8*M38*G38,2)) -> 4194.16 | O38: =ROUND(L38*N38,2) -> 822055.85 | P38: =$B$11 -> 0.02 | Q38: =ROUND(IF(L38>0,O38*P38,0),2) -> 16441.12
A39: 2028-01-01 | B39: 2 | C39: phase_2_marketplace_activation | D39: 0.94587711 | E39: =MAX(0.7,1+_xlfn.NORM.INV(RAND(),0,$B$14*0.5)) -> 1 | F39: =MAX(0.85,1+_xlfn.NORM.INV(RAND(),0,$B$14*0.4)) -> 0.947601 | G39: =MAX(0.75,1+_xlfn.NORM.INV(RAND(),0,$B$14*0.35)) -> 0.989379 | H39: =IF($B39=1,1,POWER(1+$B$9,10/12)) -> 1.024938 | I39: =IF($B39=1,E39,F39*G39) -> 0.937537 | J39: =IF($B39=1,0,$B$12+($B$13-$B$12)*(10/23)) -> 179.56522 | K39: =IF($B39=1,0,0.85+0.15*D39) -> 0.99188157 | L39: =IF($B39=1,0,MIN($B$13,MAX($B$12,ROUND(J39*K39*F39,0)))) -> 169 | M39: =IF($B39=1,0,1+($B$10*10/12)) -> 1.025 | N39: =IF($B39=1,0,ROUND($B$8*M39*G39,2)) -> 4273.02 | O39: =ROUND(L39*N39,2) -> 722139.75 | P39: =$B$11 -> 0.02 | Q39: =ROUND(IF(L39>0,O39*P39,0),2) -> 14442.79
A40: 2028-02-01 | B40: 2 | C40: phase_2_marketplace_activation | D40: 1.167967 | E40: =MAX(0.7,1+_xlfn.NORM.INV(RAND(),0,$B$14*0.5)) -> 1 | F40: =MAX(0.85,1+_xlfn.NORM.INV(RAND(),0,$B$14*0.4)) -> 0.981684 | G40: =MAX(0.75,1+_xlfn.NORM.INV(RAND(),0,$B$14*0.35)) -> 1.01533 | H40: =IF($B40=1,1,POWER(1+$B$9,11/12)) -> 1.027466 | I40: =IF($B40=1,E40,F40*G40) -> 0.996733 | J40: =IF($B40=1,0,$B$12+($B$13-$B$12)*(11/23)) -> 196.52174 | K40: =IF($B40=1,0,0.85+0.15*D40) -> 1.0251951 | L40: =IF($B40=1,0,MIN($B$13,MAX($B$12,ROUND(J40*K40*F40,0)))) -> 198 | M40: =IF($B40=1,0,1+($B$10*11/12)) -> 1.0275 | N40: =IF($B40=1,0,ROUND($B$8*M40*G40,2)) -> 4395.79 | O40: =ROUND(L40*N40,2) -> 870366.45 | P40: =$B$11 -> 0.02 | Q40: =ROUND(IF(L40>0,O40*P40,0),2) -> 17407.33
A41: 2028-03-01 | B41: 3 | C41: phase_3_projection | D41: 1 | E41: =MAX(0.7,1+_xlfn.NORM.INV(RAND(),0,$B$14*0.5)) -> 1 | F41: =MAX(0.85,1+_xlfn.NORM.INV(RAND(),0,$B$14*0.4)) -> 1.013285 | G41: =MAX(0.75,1+_xlfn.NORM.INV(RAND(),0,$B$14*0.35)) -> 0.978666 | H41: =IF($B41=1,1,POWER(1+$B$9,12/12)) -> 1.03 | I41: =IF($B41=1,E41,F41*G41) -> 0.991668 | J41: =IF($B41=1,0,$B$12+($B$13-$B$12)*(12/23)) -> 213.47826 | K41: =IF($B41=1,0,0.85+0.15*D41) -> 1 | L41: =IF($B41=1,0,MIN($B$13,MAX($B$12,ROUND(J41*K41*F41,0)))) -> 216 | M41: =IF($B41=1,0,1+($B$10*12/12)) -> 1.03 | N41: =IF($B41=1,0,ROUND($B$8*M41*G41,2)) -> 4247.37 | O41: =ROUND(L41*N41,2) -> 917430.92 | P41: =$B$11 -> 0.02 | Q41: =ROUND(IF(L41>0,O41*P41,0),2) -> 18348.62
...

Sheet MAU
A1: [MAU Assumptions] | C1: Inputs used by the MAU rollup and cohort acquisition/retention model below.
A2: name | B2: value | C2: details
A3: projection_months | B3: 36 | C3: Number of projected monthly rows in the workbook model.
A4: projection_start_month | B4: 2026-03 | C4: First month of the synthetic projection in YYYY-MM format.
A5: new_users_start | B5: 700 | C5: New users acquired in the first projected cohort month.
A6: new_users_monthly_growth_year1 | B6: 0.1 | C6: Monthly new-user growth rate applied in Year 1.
A7: new_users_monthly_growth_year2 | B7: 0.05 | C7: Monthly new-user growth rate applied in Year 2.
A8: new_users_monthly_growth_year3 | B8: 0.03 | C8: Monthly new-user growth rate applied in Year 3.
A9: new_user_holiday_spike_multiplier | B9: 1.3 | C9: Extra acquisition multiplier applied in November and December.
A10: base_new_users_rule | B10: Month 0 = start; later months = prior month * (1 + current growth rate) | C10: Human-readable formula for the base_new_users column before seasonality, holiday spike, and noise are applied.
A11: user_retention_month_1 | B11: 0.25 | C11: Share of a cohort still active one month after signup.
A12: user_retention_month_2 | B12: 0.12 | C12: Share of a cohort still active two months after signup.
A13: user_retention_month_3 | B13: 0.05 | C13: Share of a cohort still active three months after signup.
A14: user_retention_decay | B14: 0.97 | C14: Monthly decay applied to cohort retention after Month 3.
A15: jitter_std | B15: 0.05 | C15: Standard deviation used by cohort acquisition noise.
A16: dependency | B16: MAU cohort matrix on this sheet | C16: MAU is derived by summing active cohort contributions from the cohort matrix on this sheet.
A18: month | B18: year_index | C18: phase | D18: new_users | E18: returning_users | F18: mau | H18: acquisition_growth_rate | I18: base_new_users | J18: seasonality_factor | K18: noise_acquisition | M18: user_retention_age | N18: user_retained_share | O18: 2026-03-01 | P18: 2026-04-01 | Q18: 2026-05-01 | R18: 2026-06-01 | S18: 2026-07-01 | T18: 2026-08-01 | U18: 2026-09-01 | V18: 2026-10-01 | W18: 2026-11-01 | X18: 2026-12-01 | Y18: 2027-01-01 | Z18: 2027-02-01 | AA18: 2027-03-01 | AB18: 2027-04-01 | AC18: 2027-05-01 | AD18: 2027-06-01 | AE18: 2027-07-01 | AF18: 2027-08-01 | AG18: 2027-09-01 | AH18: 2027-10-01 | AI18: 2027-11-01 | AJ18: 2027-12-01 | AK18: 2028-01-01 | AL18: 2028-02-01 | AM18: 2028-03-01 | AN18: 2028-04-01 | AO18: 2028-05-01 | AP18: 2028-06-01 | AQ18: 2028-07-01 | AR18: 2028-08-01 | AS18: 2028-09-01 | AT18: 2028-10-01 | AU18: 2028-11-01 | AV18: 2028-12-01 | AW18: 2029-01-01 | AX18: 2029-02-01
A19: 2026-03-01 | B19: 1 | C19: phase_1_user_growth | D19: =ROUND(MAX(100,I19*J19*K19),0) -> 613 | E19: =MAX(0,F19-D19) -> 0 | F19: =ROUND(SUM($O$19:$O$54),0) -> 613 | H19: =IF($B19=1,$B$6,IF($B19=2,$B$7,$B$8)) -> 0.1 | I19: =$B$5 -> 700 | J19: 0.852079 | K19: =MAX(0.85,1+_xlfn.NORM.INV(RAND(),0,$B$15*0.35)) -> 1.028427 | M19: 0 | N19: =IF($M19=0,1,IF($M19=1,$B$11,IF($M19=2,$B$12,IF($M19=3,$B$13,$B$13*POWER($B$14,$M19-3)))) -> 1 | O19: =ROUND(D19*INDEX($N$19:$N$54,1),0) -> 613 | P19: =ROUND(D19*INDEX($N$19:$N$54,2),0) -> 153 | Q19: =ROUND(D19*INDEX($N$19:$N$54,3),0) -> 74 | R19: =ROUND(D19*INDEX($N$19:$N$54,4),0) -> 31 | S19: =ROUND(D19*INDEX($N$19:$N$54,5),0) -> 30 | T19: =ROUND(D19*INDEX($N$19:$N$54,6),0) -> 29 | U19: =ROUND(D19*INDEX($N$19:$N$54,7),0) -> 28 | V19: =ROUND(D19*INDEX($N$19:$N$54,8),0) -> 27 | W19: =ROUND(D19*INDEX($N$19:$N$54,9),0) -> 26 | X19: =ROUND(D19*INDEX($N$19:$N$54,10),0) -> 26 | Y19: =ROUND(D19*INDEX($N$19:$N$54,11),0) -> 25 | Z19: =ROUND(D19*INDEX($N$19:$N$54,12),0) -> 24 | AA19: =ROUND(D19*INDEX($N$19:$N$54,13),0) -> 23 | AB19: =ROUND(D19*INDEX($N$19:$N$54,14),0) -> 23 | AC19: =ROUND(D19*INDEX($N$19:$N$54,15),0) -> 22 | AD19: =ROUND(D19*INDEX($N$19:$N$54,16),0) -> 21 | AE19: =ROUND(D19*INDEX($N$19:$N$54,17),0) -> 21 | AF19: =ROUND(D19*INDEX($N$19:$N$54,18),0) -> 20 | AG19: =ROUND(D19*INDEX($N$19:$N$54,19),0) -> 19 | AH19: =ROUND(D19*INDEX($N$19:$N$54,20),0) -> 19 | AI19: =ROUND(D19*INDEX($N$19:$N$54,21),0) -> 18 | AJ19: =ROUND(D19*INDEX($N$19:$N$54,22),0) -> 18 | AK19: =ROUND(D19*INDEX($N$19:$N$54,23),0) -> 17 | AL19: =ROUND(D19*INDEX($N$19:$N$54,24),0) -> 17 | AM19: =ROUND(D19*INDEX($N$19:$N$54,25),0) -> 16 | AN19: =ROUND(D19*INDEX($N$19:$N$54,26),0) -> 16 | AO19: =ROUND(D19*INDEX($N$19:$N$54,27),0) -> 15 | AP19: =ROUND(D19*INDEX($N$19:$N$54,28),0) -> 15 | AQ19: =ROUND(D19*INDEX($N$19:$N$54,29),0) -> 14 | AR19: =ROUND(D19*INDEX($N$19:$N$54,30),0) -> 14 | AS19: =ROUND(D19*INDEX($N$19:$N$54,31),0) -> 13 | AT19: =ROUND(D19*INDEX($N$19:$N$54,32),0) -> 13 | AU19: =ROUND(D19*INDEX($N$19:$N$54,33),0) -> 13 | AV19: =ROUND(D19*INDEX($N$19:$N$54,34),0) -> 12 | AW19: =ROUND(D19*INDEX($N$19:$N$54,35),0) -> 12 | AX19: =ROUND(D19*INDEX($N$19:$N$54,36),0) -> 12
A20: 2026-04-01 | B20: 1 | C20: phase_1_user_growth | D20: =ROUND(MAX(100,I20*J20*K20),0) -> 637 | E20: =MAX(0,F20-D20) -> 153 | F20: =ROUND(SUM($P$19:$P$54),0) -> 790 | H20: =IF($B20=1,$B$6,IF($B20=2,$B$7,$B$8)) -> 0.1 | I20: =I19*(1+H20) -> 770 | J20: 0.843513 | K20: =MAX(0.85,1+_xlfn.NORM.INV(RAND(),0,$B$15*0.35)) -> 0.981037 | M20: 1 | N20: =IF($M20=0,1,IF($M20=1,$B$11,IF($M20=2,$B$12,IF($M20=3,$B$13,$B$13*POWER($B$14,$M20-3)))) -> 0.25 | P20: =ROUND(D20*INDEX($N$19:$N$54,1),0) -> 637 | Q20: =ROUND(D20*INDEX($N$19:$N$54,2),0) -> 159 | R20: =ROUND(D20*INDEX($N$19:$N$54,3),0) -> 76 | S20: =ROUND(D20*INDEX($N$19:$N$54,4),0) -> 32 | T20: =ROUND(D20*INDEX($N$19:$N$54,5),0) -> 31 | U20: =ROUND(D20*INDEX($N$19:$N$54,6),0) -> 30 | V20: =ROUND(D20*INDEX($N$19:$N$54,7),0) -> 29 | W20: =ROUND(D20*INDEX($N$19:$N$54,8),0) -> 28 | X20: =ROUND(D20*INDEX($N$19:$N$54,9),0) -> 27 | Y20: =ROUND(D20*INDEX($N$19:$N$54,10),0) -> 27 | Z20: =ROUND(D20*INDEX($N$19:$N$54,11),0) -> 26 | AA20: =ROUND(D20*INDEX($N$19:$N$54,12),0) -> 25 | AB20: =ROUND(D20*INDEX($N$19:$N$54,13),0) -> 24 | AC20: =ROUND(D20*INDEX($N$19:$N$54,14),0) -> 23 | AD20: =ROUND(D20*INDEX($N$19:$N$54,15),0) -> 23 | AE20: =ROUND(D20*INDEX($N$19:$N$54,16),0) -> 22 | AF20: =ROUND(D20*INDEX($N$19:$N$54,17),0) -> 21 | AG20: =ROUND(D20*INDEX($N$19:$N$54,18),0) -> 21 | AH20: =ROUND(D20*INDEX($N$19:$N$54,19),0) -> 20 | AI20: =ROUND(D20*INDEX($N$19:$N$54,20),0) -> 20 | AJ20: =ROUND(D20*INDEX($N$19:$N$54,21),0) -> 19 | AK20: =ROUND(D20*INDEX($N$19:$N$54,22),0) -> 18 | AL20: =ROUND(D20*INDEX($N$19:$N$54,23),0) -> 18 | AM20: =ROUND(D20*INDEX($N$19:$N$54,24),0) -> 17 | AN20: =ROUND(D20*INDEX($N$19:$N$54,25),0) -> 17 | AO20: =ROUND(D20*INDEX($N$19:$N$54,26),0) -> 16 | AP20: =ROUND(D20*INDEX($N$19:$N$54,27),0) -> 16 | AQ20: =ROUND(D20*INDEX($N$19:$N$54,28),0) -> 15 | AR20: =ROUND(D20*INDEX($N$19:$N$54,29),0) -> 15 | AS20: =ROUND(D20*INDEX($N$19:$N$54,30),0) -> 14 | AT20: =ROUND(D20*INDEX($N$19:$N$54,31),0) -> 14 | AU20: =ROUND(D20*INDEX($N$19:$N$54,32),0) -> 14 | AV20: =ROUND(D20*INDEX($N$19:$N$54,33),0) -> 13 | AW20: =ROUND(D20*INDEX($N$19:$N$54,34),0) -> 13 | AX20: =ROUND(D20*INDEX($N$19:$N$54,35),0) -> 12
A21: 2026-05-01 | B21: 1 | C21: phase_1_user_growth | D21: =ROUND(MAX(100,I21*J21*K21),0) -> 868 | E21: =MAX(0,F21-D21) -> 233 | F21: =ROUND(SUM($Q$19:$Q$54),0) -> 1101 | H21: =IF($B21=1,$B$6,IF($B21=2,$B$7,$B$8)) -> 0.1 | I21: =I20*(1+H21) -> 847 | J21: 1.01307 | K21: =MAX(0.85,1+_xlfn.NORM.INV(RAND(),0,$B$15*0.35)) -> 1.012013 | M21: 2 | N21: =IF($M21=0,1,IF($M21=1,$B$11,IF($M21=2,$B$12,IF($M21=3,$B$13,$B$13*POWER($B$14,$M21-3)))) -> 0.12 | Q21: =ROUND(D21*INDEX($N$19:$N$54,1),0) -> 868 | R21: =ROUND(D21*INDEX($N$19:$N$54,2),0) -> 217 | S21: =ROUND(D21*INDEX($N$19:$N$54,3),0) -> 104 | T21: =ROUND(D21*INDEX($N$19:$N$54,4),0) -> 43 | U21: =ROUND(D21*INDEX($N$19:$N$54,5),0) -> 42 | V21: =ROUND(D21*INDEX($N$19:$N$54,6),0) -> 41 | W21: =ROUND(D21*INDEX($N$19:$N$54,7),0) -> 40 | X21: =ROUND(D21*INDEX($N$19:$N$54,8),0) -> 38 | Y21: =ROUND(D21*INDEX($N$19:$N$54,9),0) -> 37 | Z21: =ROUND(D21*INDEX($N$19:$N$54,10),0) -> 36 | AA21: =ROUND(D21*INDEX($N$19:$N$54,11),0) -> 35 | AB21: =ROUND(D21*INDEX($N$19:$N$54,12),0) -> 34 | AC21: =ROUND(D21*INDEX($N$19:$N$54,13),0) -> 33 | AD21: =ROUND(D21*INDEX($N$19:$N$54,14),0) -> 32 | AE21: =ROUND(D21*INDEX($N$19:$N$54,15),0) -> 31 | AF21: =ROUND(D21*INDEX($N$19:$N$54,16),0) -> 30 | AG21: =ROUND(D21*INDEX($N$19:$N$54,17),0) -> 29 | AH21: =ROUND(D21*INDEX($N$19:$N$54,18),0) -> 28 | AI21: =ROUND(D21*INDEX($N$19:$N$54,19),0) -> 27 | AJ21: =ROUND(D21*INDEX($N$19:$N$54,20),0) -> 27 | AK21: =ROUND(D21*INDEX($N$19:$N$54,21),0) -> 26 | AL21: =ROUND(D21*INDEX($N$19:$N$54,22),0) -> 25 | AM21: =ROUND(D21*INDEX($N$19:$N$54,23),0) -> 24 | AN21: =ROUND(D21*INDEX($N$19:$N$54,24),0) -> 24 | AO21: =ROUND(D21*INDEX($N$19:$N$54,25),0) -> 23 | AP21: =ROUND(D21*INDEX($N$19:$N$54,26),0) -> 22 | AQ21: =ROUND(D21*INDEX($N$19:$N$54,27),0) -> 22 | AR21: =ROUND(D21*INDEX($N$19:$N$54,28),0) -> 21 | AS21: =ROUND(D21*INDEX($N$19:$N$54,29),0) -> 20 | AT21: =ROUND(D21*INDEX($N$19:$N$54,30),0) -> 20 | AU21: =ROUND(D21*INDEX($N$19:$N$54,31),0) -> 19 | AV21: =ROUND(D21*INDEX($N$19:$N$54,32),0) -> 18 | AW21: =ROUND(D21*INDEX($N$19:$N$54,33),0) -> 18 | AX21: =ROUND(D21*INDEX($N$19:$N$54,34),0) -> 17
A22: 2026-06-01 | B22: 1 | C22: phase_1_user_growth | D22: =ROUND(MAX(100,I22*J22*K22),0) -> 847 | E22: =MAX(0,F22-D22) -> 324 | F22: =ROUND(SUM($R$19:$R$54),0) -> 1171 | H22: =IF($B22=1,$B$6,IF($B22=2,$B$7,$B$8)) -> 0.1 | I22: =I21*(1+H22) -> 931.7 | J22: 0.906254 | K22: =MAX(0.85,1+_xlfn.NORM.INV(RAND(),0,$B$15*0.35)) -> 1.003557 | M22: 3 | N22: =IF($M22=0,1,IF($M22=1,$B$11,IF($M22=2,$B$12,IF($M22=3,$B$13,$B$13*POWER($B$14,$M22-3)))) -> 0.05 | R22: =ROUND(D22*INDEX($N$19:$N$54,1),0) -> 847 | S22: =ROUND(D22*INDEX($N$19:$N$54,2),0) -> 212 | T22: =ROUND(D22*INDEX($N$19:$N$54,3),0) -> 102 | U22: =ROUND(D22*INDEX($N$19:$N$54,4),0) -> 42 | V22: =ROUND(D22*INDEX($N$19:$N$54,5),0) -> 41 | W22: =ROUND(D22*INDEX($N$19:$N$54,6),0) -> 40 | X22: =ROUND(D22*INDEX($N$19:$N$54,7),0) -> 39 | Y22: =ROUND(D22*INDEX($N$19:$N$54,8),0) -> 37 | Z22: =ROUND(D22*INDEX($N$19:$N$54,9),0) -> 36 | AA22: =ROUND(D22*INDEX($N$19:$N$54,10),0) -> 35 | AB22: =ROUND(D22*INDEX($N$19:$N$54,11),0) -> 34 | AC22: =ROUND(D22*INDEX($N$19:$N$54,12),0) -> 33 | AD22: =ROUND(D22*INDEX($N$19:$N$54,13),0) -> 32 | AE22: =ROUND(D22*INDEX($N$19:$N$54,14),0) -> 31 | AF22: =ROUND(D22*INDEX($N$19:$N$54,15),0) -> 30 | AG22: =ROUND(D22*INDEX($N$19:$N$54,16),0) -> 29 | AH22: =ROUND(D22*INDEX($N$19:$N$54,17),0) -> 29 | AI22: =ROUND(D22*INDEX($N$19:$N$54,18),0) -> 28 | AJ22: =ROUND(D22*INDEX($N$19:$N$54,19),0) -> 27 | AK22: =ROUND(D22*INDEX($N$19:$N$54,20),0) -> 26 | AL22: =ROUND(D22*INDEX($N$19:$N$54,21),0) -> 25 | AM22: =ROUND(D22*INDEX($N$19:$N$54,22),0) -> 24 | AN22: =ROUND(D22*INDEX($N$19:$N$54,23),0) -> 24 | AO22: =ROUND(D22*INDEX($N$19:$N$54,24),0) -> 23 | AP22: =ROUND(D22*INDEX($N$19:$N$54,25),0) -> 22 | AQ22: =ROUND(D22*INDEX($N$19:$N$54,26),0) -> 22 | AR22: =ROUND(D22*INDEX($N$19:$N$54,27),0) -> 21 | AS22: =ROUND(D22*INDEX($N$19:$N$54,28),0) -> 20 | AT22: =ROUND(D22*INDEX($N$19:$N$54,29),0) -> 20 | AU22: =ROUND(D22*INDEX($N$19:$N$54,30),0) -> 19 | AV22: =ROUND(D22*INDEX($N$19:$N$54,31),0) -> 19 | AW22: =ROUND(D22*INDEX($N$19:$N$54,32),0) -> 18 | AX22: =ROUND(D22*INDEX($N$19:$N$54,33),0) -> 18
A23: 2026-07-01 | B23: 1 | C23: phase_1_user_growth | D23: =ROUND(MAX(100,I23*J23*K23),0) -> 915 | E23: =MAX(0,F23-D23) -> 378 | F23: =ROUND(SUM($S$19:$S$54),0) -> 1293 | H23: =IF($B23=1,$B$6,IF($B23=2,$B$7,$B$8)) -> 0.1 | I23: =I22*(1+H23) -> 1024.87 | J23: 0.891844 | K23: =MAX(0.85,1+_xlfn.NORM.INV(RAND(),0,$B$15*0.35)) -> 1.000979 | M23: 4 | N23: =IF($M23=0,1,IF($M23=1,$B$11,IF($M23=2,$B$12,IF($M23=3,$B$13,$B$13*POWER($B$14,$M23-3)))) -> 0.0485 | S23: =ROUND(D23*INDEX($N$19:$N$54,1),0) -> 915 | T23: =ROUND(D23*INDEX($N$19:$N$54,2),0) -> 229 | U23: =ROUND(D23*INDEX($N$19:$N$54,3),0) -> 110 | V23: =ROUND(D23*INDEX($N$19:$N$54,4),0) -> 46 | W23: =ROUND(D23*INDEX($N$19:$N$54,5),0) -> 44 | X23: =ROUND(D23*INDEX($N$19:$N$54,6),0) -> 43 | Y23: =ROUND(D23*INDEX($N$19:$N$54,7),0) -> 42 | Z23: =ROUND(D23*INDEX($N$19:$N$54,8),0) -> 41 | AA23: =ROUND(D23*INDEX($N$19:$N$54,9),0) -> 39 | AB23: =ROUND(D23*INDEX($N$19:$N$54,10),0) -> 38 | AC23: =ROUND(D23*INDEX($N$19:$N$54,11),0) -> 37 | AD23: =ROUND(D23*INDEX($N$19:$N$54,12),0) -> 36 | AE23: =ROUND(D23*INDEX($N$19:$N$54,13),0) -> 35 | AF23: =ROUND(D23*INDEX($N$19:$N$54,14),0) -> 34 | AG23: =ROUND(D23*INDEX($N$19:$N$54,15),0) -> 33 | AH23: =ROUND(D23*INDEX($N$19:$N$54,16),0) -> 32 | AI23: =ROUND(D23*INDEX($N$19:$N$54,17),0) -> 31 | AJ23: =ROUND(D23*INDEX($N$19:$N$54,18),0) -> 30 | AK23: =ROUND(D23*INDEX($N$19:$N$54,19),0) -> 29 | AL23: =ROUND(D23*INDEX($N$19:$N$54,20),0) -> 28 | AM23: =ROUND(D23*INDEX($N$19:$N$54,21),0) -> 27 | AN23: =ROUND(D23*INDEX($N$19:$N$54,22),0) -> 26 | AO23: =ROUND(D23*INDEX($N$19:$N$54,23),0) -> 26 | AP23: =ROUND(D23*INDEX($N$19:$N$54,24),0) -> 25 | AQ23: =ROUND(D23*INDEX($N$19:$N$54,25),0) -> 24 | AR23: =ROUND(D23*INDEX($N$19:$N$54,26),0) -> 23 | AS23: =ROUND(D23*INDEX($N$19:$N$54,27),0) -> 23 | AT23: =ROUND(D23*INDEX($N$19:$N$54,28),0) -> 22 | AU23: =ROUND(D23*INDEX($N$19:$N$54,29),0) -> 21 | AV23: =ROUND(D23*INDEX($N$19:$N$54,30),0) -> 21 | AW23: =ROUND(D23*INDEX($N$19:$N$54,31),0) -> 20 | AX23: =ROUND(D23*INDEX($N$19:$N$54,32),0) -> 19
A24: 2026-08-01 | B24: 1 | C24: phase_1_user_growth | D24: =ROUND(MAX(100,I24*J24*K24),0) -> 1069 | E24: =MAX(0,F24-D24) -> 434 | F24: =ROUND(SUM($T$19:$T$54),0) -> 1503 | H24: =IF($B24=1,$B$6,IF($B24=2,$B$7,$B$8)) -> 0.1 | I24: =I23*(1+H24) -> 1127.36 | J24: 0.921643 | K24: =MAX(0.85,1+_xlfn.NORM.INV(RAND(),0,$B$15*0.35)) -> 1.028426 | M24: 5 | N24: =IF($M24=0,1,IF($M24=1,$B$11,IF($M24=2,$B$12,IF($M24=3,$B$13,$B$13*POWER($B$14,$M24-3)))) -> 0.047045 | T24: =ROUND(D24*INDEX($N$19:$N$54,1),0) -> 1069 | U24: =ROUND(D24*INDEX($N$19:$N$54,2),0) -> 267 | V24: =ROUND(D24*INDEX($N$19:$N$54,3),0) -> 128 | W24: =ROUND(D24*INDEX($N$19:$N$54,4),0) -> 53 | X24: =ROUND(D24*INDEX($N$19:$N$54,5),0) -> 52 | Y24: =ROUND(D24*INDEX($N$19:$N$54,6),0) -> 50 | Z24: =ROUND(D24*INDEX($N$19:$N$54,7),0) -> 49 | AA24: =ROUND(D24*INDEX($N$19:$N$54,8),0) -> 47 | AB24: =ROUND(D24*INDEX($N$19:$N$54,9),0) -> 46 | AC24: =ROUND(D24*INDEX($N$19:$N$54,10),0) -> 45 | AD24: =ROUND(D24*INDEX($N$19:$N$54,11),0) -> 43 | AE24: =ROUND(D24*INDEX($N$19:$N$54,12),0) -> 42 | AF24: =ROUND(D24*INDEX($N$19:$N$54,13),0) -> 41 | AG24: =ROUND(D24*INDEX($N$19:$N$54,14),0) -> 39 | AH24: =ROUND(D24*INDEX($N$19:$N$54,15),0) -> 38 | AI24: =ROUND(D24*INDEX($N$19:$N$54,16),0) -> 37 | AJ24: =ROUND(D24*INDEX($N$19:$N$54,17),0) -> 36 | AK24: =ROUND(D24*INDEX($N$19:$N$54,18),0) -> 35 | AL24: =ROUND(D24*INDEX($N$19:$N$54,19),0) -> 34 | AM24: =ROUND(D24*INDEX($N$19:$N$54,20),0) -> 33 | AN24: =ROUND(D24*INDEX($N$19:$N$54,21),0) -> 32 | AO24: =ROUND(D24*INDEX($N$19:$N$54,22),0) -> 31 | AP24: =ROUND(D24*INDEX($N$19:$N$54,23),0) -> 30 | AQ24: =ROUND(D24*INDEX($N$19:$N$54,24),0) -> 29 | AR24: =ROUND(D24*INDEX($N$19:$N$54,25),0) -> 28 | AS24: =ROUND(D24*INDEX($N$19:$N$54,26),0) -> 27 | AT24: =ROUND(D24*INDEX($N$19:$N$54,27),0) -> 27 | AU24: =ROUND(D24*INDEX($N$19:$N$54,28),0) -> 26 | AV24: =ROUND(D24*INDEX($N$19:$N$54,29),0) -> 25 | AW24: =ROUND(D24*INDEX($N$19:$N$54,30),0) -> 24 | AX24: =ROUND(D24*INDEX($N$19:$N$54,31),0) -> 23
A25: 2026-09-01 | B25: 1 | C25: phase_1_user_growth | D25: =ROUND(MAX(100,I25*J25*K25),0) -> 1074 | E25: =MAX(0,F25-D25) -> 519 | F25: =ROUND(SUM($U$19:$U$54),0) -> 1593 | H25: =IF($B25=1,$B$6,IF($B25=2,$B$7,$B$8)) -> 0.1 | I25: =I24*(1+H25) -> 1240.09 | J25: 0.885988 | K25: =MAX(0.85,1+_xlfn.NORM.INV(RAND(),0,$B$15*0.35)) -> 0.977212 | M25: 6 | N25: =IF($M25=0,1,IF($M25=1,$B$11,IF($M25=2,$B$12,IF($M25=3,$B$13,$B$13*POWER($B$14,$M25-3)))) -> 0.04563365 | U25: =ROUND(D25*INDEX($N$19:$N$54,1),0) -> 1074 | V25: =ROUND(D25*INDEX($N$19:$N$54,2),0) -> 268 | W25: =ROUND(D25*INDEX($N$19:$N$54,3),0) -> 129 | X25: =ROUND(D25*INDEX($N$19:$N$54,4),0) -> 54 | Y25: =ROUND(D25*INDEX($N$19:$N$54,5),0) -> 52 | Z25: =ROUND(D25*INDEX($N$19:$N$54,6),0) -> 51 | AA25: =ROUND(D25*INDEX($N$19:$N$54,7),0) -> 49 | AB25: =ROUND(D25*INDEX($N$19:$N$54,8),0) -> 48 | AC25: =ROUND(D25*INDEX($N$19:$N$54,9),0) -> 46 | AD25: =ROUND(D25*INDEX($N$19:$N$54,10),0) -> 45 | AE25: =ROUND(D25*INDEX($N$19:$N$54,11),0) -> 43 | AF25: =ROUND(D25*INDEX($N$19:$N$54,12),0) -> 42 | AG25: =ROUND(D25*INDEX($N$19:$N$54,13),0) -> 41 | AH25: =ROUND(D25*INDEX($N$19:$N$54,14),0) -> 40 | AI25: =ROUND(D25*INDEX($N$19:$N$54,15),0) -> 38 | AJ25: =ROUND(D25*INDEX($N$19:$N$54,16),0) -> 37 | AK25: =ROUND(D25*INDEX($N$19:$N$54,17),0) -> 36 | AL25: =ROUND(D25*INDEX($N$19:$N$54,18),0) -> 35 | AM25: =ROUND(D25*INDEX($N$19:$N$54,19),0) -> 34 | AN25: =ROUND(D25*INDEX($N$19:$N$54,20),0) -> 33 | AO25: =ROUND(D25*INDEX($N$19:$N$54,21),0) -> 32 | AP25: =ROUND(D25*INDEX($N$19:$N$54,22),0) -> 31 | AQ25: =ROUND(D25*INDEX($N$19:$N$54,23),0) -> 30 | AR25: =ROUND(D25*INDEX($N$19:$N$54,24),0) -> 29 | AS25: =ROUND(D25*INDEX($N$19:$N$54,25),0) -> 28 | AT25: =ROUND(D25*INDEX($N$19:$N$54,26),0) -> 27 | AU25: =ROUND(D25*INDEX($N$19:$N$54,27),0) -> 27 | AV25: =ROUND(D25*INDEX($N$19:$N$54,28),0) -> 26 | AW25: =ROUND(D25*INDEX($N$19:$N$54,29),0) -> 25 | AX25: =ROUND(D25*INDEX($N$19:$N$54,30),0) -> 24
A26: 2026-10-01 | B26: 1 | C26: phase_1_user_growth | D26: =ROUND(MAX(100,I26*J26*K26),0) -> 1244 | E26: =MAX(0,F26-D26) -> 580 | F26: =ROUND(SUM($V$19:$V$54),0) -> 1824 | H26: =IF($B26=1,$B$6,IF($B26=2,$B$7,$B$8)) -> 0.1 | I26: =I25*(1+H26) -> 1364.1 | J26: 0.911037 | K26: =MAX(0.85,1+_xlfn.NORM.INV(RAND(),0,$B$15*0.35)) -> 1.000724 | M26: 7 | N26: =IF($M26=0,1,IF($M26=1,$B$11,IF($M26=2,$B$12,IF($M26=3,$B$13,$B$13*POWER($B$14,$M26-3)))) -> 0.044264641 | V26: =ROUND(D26*INDEX($N$19:$N$54,1),0) -> 1244 | W26: =ROUND(D26*INDEX($N$19:$N$54,2),0) -> 311 | X26: =ROUND(D26*INDEX($N$19:$N$54,3),0) -> 149 | Y26: =ROUND(D26*INDEX($N$19:$N$54,4),0) -> 62 | Z26: =ROUND(D26*INDEX($N$19:$N$54,5),0) -> 60 | AA26: =ROUND(D26*INDEX($N$19:$N$54,6),0) -> 59 | AB26: =ROUND(D26*INDEX($N$19:$N$54,7),0) -> 57 | AC26: =ROUND(D26*INDEX($N$19:$N$54,8),0) -> 55 | AD26: =ROUND(D26*INDEX($N$19:$N$54,9),0) -> 53 | AE26: =ROUND(D26*INDEX($N$19:$N$54,10),0) -> 52 | AF26: =ROUND(D26*INDEX($N$19:$N$54,11),0) -> 50 | AG26: =ROUND(D26*INDEX($N$19:$N$54,12),0) -> 49 | AH26: =ROUND(D26*INDEX($N$19:$N$54,13),0) -> 47 | AI26: =ROUND(D26*INDEX($N$19:$N$54,14),0) -> 46 | AJ26: =ROUND(D26*INDEX($N$19:$N$54,15),0) -> 44 | AK26: =ROUND(D26*INDEX($N$19:$N$54,16),0) -> 43 | AL26: =ROUND(D26*INDEX($N$19:$N$54,17),0) -> 42 | AM26: =ROUND(D26*INDEX($N$19:$N$54,18),0) -> 41 | AN26: =ROUND(D26*INDEX($N$19:$N$54,19),0) -> 39 | AO26: =ROUND(D26*INDEX($N$19:$N$54,20),0) -> 38 | AP26: =ROUND(D26*INDEX($N$19:$N$54,21),0) -> 37 | AQ26: =ROUND(D26*INDEX($N$19:$N$54,22),0) -> 36 | AR26: =ROUND(D26*INDEX($N$19:$N$54,23),0) -> 35 | AS26: =ROUND(D26*INDEX($N$19:$N$54,24),0) -> 34 | AT26: =ROUND(D26*INDEX($N$19:$N$54,25),0) -> 33 | AU26: =ROUND(D26*INDEX($N$19:$N$54,26),0) -> 32 | AV26: =ROUND(D26*INDEX($N$19:$N$54,27),0) -> 31 | AW26: =ROUND(D26*INDEX($N$19:$N$54,28),0) -> 30 | AX26: =ROUND(D26*INDEX($N$19:$N$54,29),0) -> 29
A27: 2026-11-01 | B27: 1 | C27: phase_1_user_growth | D27: =ROUND(MAX(100,I27*J27*K27),0) -> 2020 | E27: =MAX(0,F27-D27) -> 671 | F27: =ROUND(SUM($W$19:$W$54),0) -> 2691 | H27: =IF($B27=1,$B$6,IF($B27=2,$B$7,$B$8)) -> 0.1 | I27: =I26*(1+H27) -> 1500.51 | J27: 1.344002 | K27: =MAX(0.85,1+_xlfn.NORM.INV(RAND(),0,$B$15*0.35)) -> 1.001745 | M27: 8 | N27: =IF($M27=0,1,IF($M27=1,$B$11,IF($M27=2,$B$12,IF($M27=3,$B$13,$B$13*POWER($B$14,$M27-3)))) -> 0.042936701 | W27: =ROUND(D27*INDEX($N$19:$N$54,1),0) -> 2020 | X27: =ROUND(D27*INDEX($N$19:$N$54,2),0) -> 505 | Y27: =ROUND(D27*INDEX($N$19:$N$54,3),0) -> 242 | Z27: =ROUND(D27*INDEX($N$19:$N$54,4),0) -> 101 | AA27: =ROUND(D27*INDEX($N$19:$N$54,5),0) -> 98 | AB27: =ROUND(D27*INDEX($N$19:$N$54,6),0) -> 95 | AC27: =ROUND(D27*INDEX($N$19:$N$54,7),0) -> 92 | AD27: =ROUND(D27*INDEX($N$19:$N$54,8),0) -> 89 | AE27: =ROUND(D27*INDEX($N$19:$N$54,9),0) -> 87 | AF27: =ROUND(D27*INDEX($N$19:$N$54,10),0) -> 84 | AG27: =ROUND(D27*INDEX($N$19:$N$54,11),0) -> 82 | AH27: =ROUND(D27*INDEX($N$19:$N$54,12),0) -> 79 | AI27: =ROUND(D27*INDEX($N$19:$N$54,13),0) -> 77 | AJ27: =ROUND(D27*INDEX($N$19:$N$54,14),0) -> 74 | AK27: =ROUND(D27*INDEX($N$19:$N$54,15),0) -> 72 | AL27: =ROUND(D27*INDEX($N$19:$N$54,16),0) -> 70 | AM27: =ROUND(D27*INDEX($N$19:$N$54,17),0) -> 68 | AN27: =ROUND(D27*INDEX($N$19:$N$54,18),0) -> 66 | AO27: =ROUND(D27*INDEX($N$19:$N$54,19),0) -> 64 | AP27: =ROUND(D27*INDEX($N$19:$N$54,20),0) -> 62 | AQ27: =ROUND(D27*INDEX($N$19:$N$54,21),0) -> 60 | AR27: =ROUND(D27*INDEX($N$19:$N$54,22),0) -> 58 | AS27: =ROUND(D27*INDEX($N$19:$N$54,23),0) -> 57 | AT27: =ROUND(D27*INDEX($N$19:$N$54,24),0) -> 55 | AU27: =ROUND(D27*INDEX($N$19:$N$54,25),0) -> 53 | AV27: =ROUND(D27*INDEX($N$19:$N$54,26),0) -> 52 | AW27: =ROUND(D27*INDEX($N$19:$N$54,27),0) -> 50 | AX27: =ROUND(D27*INDEX($N$19:$N$54,28),0) -> 49
A28: 2026-12-01 | B28: 1 | C28: phase_1_user_growth | D28: =ROUND(MAX(100,I28*J28*K28),0) -> 4065 | E28: =MAX(0,F28-D28) -> 933 | F28: =ROUND(SUM($X$19:$X$54),0) -> 4998 | H28: =IF($B28=1,$B$6,IF($B28=2,$B$7,$B$8)) -> 0.1 | I28: =I27*(1+H28) -> 1650.56 | J28: 2.521434 | K28: =MAX(0.85,1+_xlfn.NORM.INV(RAND(),0,$B$15*0.35)) -> 0.976809 | M28: 9 | N28: =IF($M28=0,1,IF($M28=1,$B$11,IF($M28=2,$B$12,IF($M28=3,$B$13,$B$13*POWER($B$14,$M28-3)))) -> 0.0416486 | X28: =ROUND(D28*INDEX($N$19:$N$54,1),0) -> 4065 | Y28: =ROUND(D28*INDEX($N$19:$N$54,2),0) -> 1016 | Z28: =ROUND(D28*INDEX($N$19:$N$54,3),0) -> 488 | AA28: =ROUND(D28*INDEX($N$19:$N$54,4),0) -> 203 | AB28: =ROUND(D28*INDEX($N$19:$N$54,5),0) -> 197 | AC28: =ROUND(D28*INDEX($N$19:$N$54,6),0) -> 191 | AD28: =ROUND(D28*INDEX($N$19:$N$54,7),0) -> 186 | AE28: =ROUND(D28*INDEX($N$19:$N$54,8),0) -> 180 | AF28: =ROUND(D28*INDEX($N$19:$N$54,9),0) -> 175 | AG28: =ROUND(D28*INDEX($N$19:$N$54,10),0) -> 169 | AH28: =ROUND(D28*INDEX($N$19:$N$54,11),0) -> 164 | AI28: =ROUND(D28*INDEX($N$19:$N$54,12),0) -> 159 | AJ28: =ROUND(D28*INDEX($N$19:$N$54,13),0) -> 155 | AK28: =ROUND(D28*INDEX($N$19:$N$54,14),0) -> 150 | AL28: =ROUND(D28*INDEX($N$19:$N$54,15),0) -> 145 | AM28: =ROUND(D28*INDEX($N$19:$N$54,16),0) -> 141 | AN28: =ROUND(D28*INDEX($N$19:$N$54,17),0) -> 137 | AO28: =ROUND(D28*INDEX($N$19:$N$54,18),0) -> 133 | AP28: =ROUND(D28*INDEX($N$19:$N$54,19),0) -> 129 | AQ28: =ROUND(D28*INDEX($N$19:$N$54,20),0) -> 125 | AR28: =ROUND(D28*INDEX($N$19:$N$54,21),0) -> 121 | AS28: =ROUND(D28*INDEX($N$19:$N$54,22),0) -> 117 | AT28: =ROUND(D28*INDEX($N$19:$N$54,23),0) -> 114 | AU28: =ROUND(D28*INDEX($N$19:$N$54,24),0) -> 111 | AV28: =ROUND(D28*INDEX($N$19:$N$54,25),0) -> 107 | AW28: =ROUND(D28*INDEX($N$19:$N$54,26),0) -> 104 | AX28: =ROUND(D28*INDEX($N$19:$N$54,27),0) -> 101
A29: 2027-01-01 | B29: 1 | C29: phase_1_user_growth | D29: =ROUND(MAX(100,I29*J29*K29),0) -> 1470 | E29: =MAX(0,F29-D29) -> 1590 | F29: =ROUND(SUM($Y$19:$Y$54),0) -> 3060 | H29: =IF($B29=1,$B$6,IF($B29=2,$B$7,$B$8)) -> 0.1 | I29: =I28*(1+H29) -> 1815.62 | J29: 0.805962 | K29: =MAX(0.85,1+_xlfn.NORM.INV(RAND(),0,$B$15*0.35)) -> 1.004354 | M29: 10 | N29: =IF($M29=0,1,IF($M29=1,$B$11,IF($M29=2,$B$12,IF($M29=3,$B$13,$B$13*POWER($B$14,$M29-3)))) -> 0.040399142 | Y29: =ROUND(D29*INDEX($N$19:$N$54,1),0) -> 1470 | Z29: =ROUND(D29*INDEX($N$19:$N$54,2),0) -> 368 | AA29: =ROUND(D29*INDEX($N$19:$N$54,3),0) -> 176 | AB29: =ROUND(D29*INDEX($N$19:$N$54,4),0) -> 74 | AC29: =ROUND(D29*INDEX($N$19:$N$54,5),0) -> 71 | AD29: =ROUND(D29*INDEX($N$19:$N$54,6),0) -> 69 | AE29: =ROUND(D29*INDEX($N$19:$N$54,7),0) -> 67 | AF29: =ROUND(D29*INDEX($N$19:$N$54,8),0) -> 65 | AG29: =ROUND(D29*INDEX($N$19:$N$54,9),0) -> 63 | AH29: =ROUND(D29*INDEX($N$19:$N$54,10),0) -> 61 | AI29: =ROUND(D29*INDEX($N$19:$N$54,11),0) -> 59 | AJ29: =ROUND(D29*INDEX($N$19:$N$54,12),0) -> 58 | AK29: =ROUND(D29*INDEX($N$19:$N$54,13),0) -> 56 | AL29: =ROUND(D29*INDEX($N$19:$N$54,14),0) -> 54 | AM29: =ROUND(D29*INDEX($N$19:$N$54,15),0) -> 53 | AN29: =ROUND(D29*INDEX($N$19:$N$54,16),0) -> 51 | AO29: =ROUND(D29*INDEX($N$19:$N$54,17),0) -> 49 | AP29: =ROUND(D29*INDEX($N$19:$N$54,18),0) -> 48 | AQ29: =ROUND(D29*INDEX($N$19:$N$54,19),0) -> 47 | AR29: =ROUND(D29*INDEX($N$19:$N$54,20),0) -> 45 | AS29: =ROUND(D29*INDEX($N$19:$N$54,21),0) -> 44 | AT29: =ROUND(D29*INDEX($N$19:$N$54,22),0) -> 42 | AU29: =ROUND(D29*INDEX($N$19:$N$54,23),0) -> 41 | AV29: =ROUND(D29*INDEX($N$19:$N$54,24),0) -> 40 | AW29: =ROUND(D29*INDEX($N$19:$N$54,25),0) -> 39 | AX29: =ROUND(D29*INDEX($N$19:$N$54,26),0) -> 38
A30: 2027-02-01 | B30: 1 | C30: phase_1_user_growth | D30: =ROUND(MAX(100,I30*J30*K30),0) -> 1974 | E30: =MAX(0,F30-D30) -> 1280 | F30: =ROUND(SUM($Z$19:$Z$54),0) -> 3254 | H30: =IF($B30=1,$B$6,IF($B30=2,$B$7,$B$8)) -> 0.1 | I30: =I29*(1+H30) -> 1997.18 | J30: 0.9952 | K30: =MAX(0.85,1+_xlfn.NORM.INV(RAND(),0,$B$15*0.35)) -> 0.993253 | M30: 11 | N30: =IF($M30=0,1,IF($M30=1,$B$11,IF($M30=2,$B$12,IF($M30=3,$B$13,$B$13*POWER($B$14,$M30-3)))) -> 0.039187168 | Z30: =ROUND(D30*INDEX($N$19:$N$54,1),0) -> 1974 | AA30: =ROUND(D30*INDEX($N$19:$N$54,2),0) -> 494 | AB30: =ROUND(D30*INDEX($N$19:$N$54,3),0) -> 237 | AC30: =ROUND(D30*INDEX($N$19:$N$54,4),0) -> 99 | AD30: =ROUND(D30*INDEX($N$19:$N$54,5),0) -> 96 | AE30: =ROUND(D30*INDEX($N$19:$N$54,6),0) -> 93 | AF30: =ROUND(D30*INDEX($N$19:$N$54,7),0) -> 90 | AG30: =ROUND(D30*INDEX($N$19:$N$54,8),0) -> 87 | AH30: =ROUND(D30*INDEX($N$19:$N$54,9),0) -> 85 | AI30: =ROUND(D30*INDEX($N$19:$N$54,10),0) -> 82 | AJ30: =ROUND(D30*INDEX($N$19:$N$54,11),0) -> 80 | AK30: =ROUND(D30*INDEX($N$19:$N$54,12),0) -> 77 | AL30: =ROUND(D30*INDEX($N$19:$N$54,13),0) -> 75 | AM30: =ROUND(D30*INDEX($N$19:$N$54,14),0) -> 73 | AN30: =ROUND(D30*INDEX($N$19:$N$54,15),0) -> 71 | AO30: =ROUND(D30*INDEX($N$19:$N$54,16),0) -> 68 | AP30: =ROUND(D30*INDEX($N$19:$N$54,17),0) -> 66 | AQ30: =ROUND(D30*INDEX($N$19:$N$54,18),0) -> 64 | AR30: =ROUND(D30*INDEX($N$19:$N$54,19),0) -> 63 | AS30: =ROUND(D30*INDEX($N$19:$N$54,20),0) -> 61 | AT30: =ROUND(D30*INDEX($N$19:$N$54,21),0) -> 59 | AU30: =ROUND(D30*INDEX($N$19:$N$54,22),0) -> 57 | AV30: =ROUND(D30*INDEX($N$19:$N$54,23),0) -> 55 | AW30: =ROUND(D30*INDEX($N$19:$N$54,24),0) -> 54 | AX30: =ROUND(D30*INDEX($N$19:$N$54,25),0) -> 52
A31: 2027-03-01 | B31: 2 | C31: phase_2_marketplace_activation | D31: =ROUND(MAX(100,I31*J31*K31),0) -> 1725 | E31: =MAX(0,F31-D31) -> 1283 | F31: =ROUND(SUM($AA$19:$AA$54),0) -> 3008 | H31: =IF($B31=1,$B$6,IF($B31=2,$B$7,$B$8)) -> 0.05 | I31: =I30*(1+H31) -> 2097.04 | J31: 0.852079 | K31: =MAX(0.85,1+_xlfn.NORM.INV(RAND(),0,$B$15*0.35)) -> 0.965491 | M31: 12 | N31: =IF($M31=0,1,IF($M31=1,$B$11,IF($M31=2,$B$12,IF($M31=3,$B$13,$B$13*POWER($B$14,$M31-3)))) -> 0.038011553 | AA31: =ROUND(D31*INDEX($N$19:$N$54,1),0) -> 1725 | AB31: =ROUND(D31*INDEX($N$19:$N$54,2),0) -> 431 | AC31: =ROUND(D31*INDEX($N$19:$N$54,3),0) -> 207 | AD31: =ROUND(D31*INDEX($N$19:$N$54,4),0) -> 86 | AE31: =ROUND(D31*INDEX($N$19:$N$54,5),0) -> 84 | AF31: =ROUND(D31*INDEX($N$19:$N$54,6),0) -> 81 | AG31: =ROUND(D31*INDEX($N$19:$N$54,7),0) -> 79 | AH31: =ROUND(D31*INDEX($N$19:$N$54,8),0) -> 76 | AI31: =ROUND(D31*INDEX($N$19:$N$54,9),0) -> 74 | AJ31: =ROUND(D31*INDEX($N$19:$N$54,10),0) -> 72 | AK31: =ROUND(D31*INDEX($N$19:$N$54,11),0) -> 70 | AL31: =ROUND(D31*INDEX($N$19:$N$54,12),0) -> 68 | AM31: =ROUND(D31*INDEX($N$19:$N$54,13),0) -> 66 | AN31: =ROUND(D31*INDEX($N$19:$N$54,14),0) -> 64 | AO31: =ROUND(D31*INDEX($N$19:$N$54,15),0) -> 62 | AP31: =ROUND(D31*INDEX($N$19:$N$54,16),0) -> 60 | AQ31: =ROUND(D31*INDEX($N$19:$N$54,17),0) -> 58 | AR31: =ROUND(D31*INDEX($N$19:$N$54,18),0) -> 56 | AS31: =ROUND(D31*INDEX($N$19:$N$54,19),0) -> 55 | AT31: =ROUND(D31*INDEX($N$19:$N$54,20),0) -> 53 | AU31: =ROUND(D31*INDEX($N$19:$N$54,21),0) -> 51 | AV31: =ROUND(D31*INDEX($N$19:$N$54,22),0) -> 50 | AW31: =ROUND(D31*INDEX($N$19:$N$54,23),0) -> 48 | AX31: =ROUND(D31*INDEX($N$19:$N$54,24),0) -> 47
A32: 2027-04-01 | B32: 2 | C32: phase_2_marketplace_activation | D32: =ROUND(MAX(100,I32*J32*K32),0) -> 1806 | E32: =MAX(0,F32-D32) -> 1338 | F32: =ROUND(SUM($AB$19:$AB$54),0) -> 3144 | H32: =IF($B32=1,$B$6,IF($B32=2,$B$7,$B$8)) -> 0.05 | I32: =I31*(1+H32) -> 2201.89 | J32: 0.843513 | K32: =MAX(0.85,1+_xlfn.NORM.INV(RAND(),0,$B$15*0.35)) -> 0.972386 | M32: 13 | N32: =IF($M32=0,1,IF($M32=1,$B$11,IF($M32=2,$B$12,IF($M32=3,$B$13,$B$13*POWER($B$14,$M32-3)))) -> 0.036871206 | AB32: =ROUND(D32*INDEX($N$19:$N$54,1),0) -> 1806 | AC32: =ROUND(D32*INDEX($N$19:$N$54,2),0) -> 452 | AD32: =ROUND(D32*INDEX($N$19:$N$54,3),0) -> 217 | AE32: =ROUND(D32*INDEX($N$19:$N$54,4),0) -> 90 | AF32: =ROUND(D32*INDEX($N$19:$N$54,5),0) -> 88 | AG32: =ROUND(D32*INDEX($N$19:$N$54,6),0) -> 85 | AH32: =ROUND(D32*INDEX($N$19:$N$54,7),0) -> 82 | AI32: =ROUND(D32*INDEX($N$19:$N$54,8),0) -> 80 | AJ32: =ROUND(D32*INDEX($N$19:$N$54,9),0) -> 78 | AK32: =ROUND(D32*INDEX($N$19:$N$54,10),0) -> 75 | AL32: =ROUND(D32*INDEX($N$19:$N$54,11),0) -> 73 | AM32: =ROUND(D32*INDEX($N$19:$N$54,12),0) -> 71 | AN32: =ROUND(D32*INDEX($N$19:$N$54,13),0) -> 69 | AO32: =ROUND(D32*INDEX($N$19:$N$54,14),0) -> 67 | AP32: =ROUND(D32*INDEX($N$19:$N$54,15),0) -> 65 | AQ32: =ROUND(D32*INDEX($N$19:$N$54,16),0) -> 63 | AR32: =ROUND(D32*INDEX($N$19:$N$54,17),0) -> 61 | AS32: =ROUND(D32*INDEX($N$19:$N$54,18),0) -> 59 | AT32: =ROUND(D32*INDEX($N$19:$N$54,19),0) -> 57 | AU32: =ROUND(D32*INDEX($N$19:$N$54,20),0) -> 55 | AV32: =ROUND(D32*INDEX($N$19:$N$54,21),0) -> 54 | AW32: =ROUND(D32*INDEX($N$19:$N$54,22),0) -> 52 | AX32: =ROUND(D32*INDEX($N$19:$N$54,23),0) -> 51
A33: 2027-05-01 | B33: 2 | C33: phase_2_marketplace_activation | D33: =ROUND(MAX(100,I33*J33*K33),0) -> 2329 | E33: =MAX(0,F33-D33) -> 1406 | F33: =ROUND(SUM($AC$19:$AC$54),0) -> 3735 | H33: =IF($B33=1,$B$6,IF($B33=2,$B$7,$B$8)) -> 0.05 | I33: =I32*(1+H33) -> 2311.99 | J33: 1.01307 | K33: =MAX(0.85,1+_xlfn.NORM.INV(RAND(),0,$B$15*0.35)) -> 0.994418 | M33: 14 | N33: =IF($M33=0,1,IF($M33=1,$B$11,IF($M33=2,$B$12,IF($M33=3,$B$13,$B$13*POWER($B$14,$M33-3)))) -> 0.03576507 | AC33: =ROUND(D33*INDEX($N$19:$N$54,1),0) -> 2329 | AD33: =ROUND(D33*INDEX($N$19:$N$54,2),0) -> 582 | AE33: =ROUND(D33*INDEX($N$19:$N$54,3),0) -> 279 | AF33: =ROUND(D33*INDEX($N$19:$N$54,4),0) -> 116 | AG33: =ROUND(D33*INDEX($N$19:$N$54,5),0) -> 113 | AH33: =ROUND(D33*INDEX($N$19:$N$54,6),0) -> 110 | AI33: =ROUND(D33*INDEX($N$19:$N$54,7),0) -> 106 | AJ33: =ROUND(D33*INDEX($N$19:$N$54,8),0) -> 103 | AK33: =ROUND(D33*INDEX($N$19:$N$54,9),0) -> 100 | AL33: =ROUND(D33*INDEX($N$19:$N$54,10),0) -> 97 | AM33: =ROUND(D33*INDEX($N$19:$N$54,11),0) -> 94 | AN33: =ROUND(D33*INDEX($N$19:$N$54,12),0) -> 91 | AO33: =ROUND(D33*INDEX($N$19:$N$54,13),0) -> 89 | AP33: =ROUND(D33*INDEX($N$19:$N$54,14),0) -> 86 | AQ33: =ROUND(D33*INDEX($N$19:$N$54,15),0) -> 83 | AR33: =ROUND(D33*INDEX($N$19:$N$54,16),0) -> 81 | AS33: =ROUND(D33*INDEX($N$19:$N$54,17),0) -> 78 | AT33: =ROUND(D33*INDEX($N$19:$N$54,18),0) -> 76 | AU33: =ROUND(D33*INDEX($N$19:$N$54,19),0) -> 74 | AV33: =ROUND(D33*INDEX($N$19:$N$54,20),0) -> 72 | AW33: =ROUND(D33*INDEX($N$19:$N$54,21),0) -> 69 | AX33: =ROUND(D33*INDEX($N$19:$N$54,22),0) -> 67
A34: 2027-06-01 | B34: 2 | C34: phase_2_marketplace_activation | D34: =ROUND(MAX(100,I34*J34*K34),0) -> 2186 | E34: =MAX(0,F34-D34) -> 1610 | F34: =ROUND(SUM($AD$19:$AD$54),0) -> 3796 | H34: =IF($B34=1,$B$6,IF($B34=2,$B$7,$B$8)) -> 0.05 | I34: =I33*(1+H34) -> 2427.59 | J34: 0.906254 | K34: =MAX(0.85,1+_xlfn.NORM.INV(RAND(),0,$B$15*0.35)) -> 0.993475 | M34: 15 | N34: =IF($M34=0,1,IF($M34=1,$B$11,IF($M34=2,$B$12,IF($M34=3,$B$13,$B$13*POWER($B$14,$M34-3)))) -> 0.034692118 | AD34: =ROUND(D34*INDEX($N$19:$N$54,1),0) -> 2186 | AE34: =ROUND(D34*INDEX($N$19:$N$54,2),0) -> 546 | AF34: =ROUND(D34*INDEX($N$19:$N$54,3),0) -> 262 | AG34: =ROUND(D34*INDEX($N$19:$N$54,4),0) -> 109 | AH34: =ROUND(D34*INDEX($N$19:$N$54,5),0) -> 106 | AI34: =ROUND(D34*INDEX($N$19:$N$54,6),0) -> 103 | AJ34: =ROUND(D34*INDEX($N$19:$N$54,7),0) -> 100 | AK34: =ROUND(D34*INDEX($N$19:$N$54,8),0) -> 97 | AL34: =ROUND(D34*INDEX($N$19:$N$54,9),0) -> 94 | AM34: =ROUND(D34*INDEX($N$19:$N$54,10),0) -> 91 | AN34: =ROUND(D34*INDEX($N$19:$N$54,11),0) -> 88 | AO34: =ROUND(D34*INDEX($N$19:$N$54,12),0) -> 86 | AP34: =ROUND(D34*INDEX($N$19:$N$54,13),0) -> 83 | AQ34: =ROUND(D34*INDEX($N$19:$N$54,14),0) -> 81 | AR34: =ROUND(D34*INDEX($N$19:$N$54,15),0) -> 78 | AS34: =ROUND(D34*INDEX($N$19:$N$54,16),0) -> 76 | AT34: =ROUND(D34*INDEX($N$19:$N$54,17),0) -> 74 | AU34: =ROUND(D34*INDEX($N$19:$N$54,18),0) -> 71 | AV34: =ROUND(D34*INDEX($N$19:$N$54,19),0) -> 69 | AW34: =ROUND(D34*INDEX($N$19:$N$54,20),0) -> 67 | AX34: =ROUND(D34*INDEX($N$19:$N$54,21),0) -> 65
A35: 2027-07-01 | B35: 2 | C35: phase_2_marketplace_activation | D35: =ROUND(MAX(100,I35*J35*K35),0) -> 2343 | E35: =MAX(0,F35-D35) -> 1703 | F35: =ROUND(SUM($AE$19:$AE$54),0) -> 4046 | H35: =IF($B35=1,$B$6,IF($B35=2,$B$7,$B$8)) -> 0.05 | I35: =I34*(1+H35) -> 2548.97 | J35: 0.891844 | K35: =MAX(0.85,1+_xlfn.NORM.INV(RAND(),0,$B$15*0.35)) -> 1.030481 | M35: 16 | N35: =IF($M35=0,1,IF($M35=1,$B$11,IF($M35=2,$B$12,IF($M35=3,$B$13,$B$13*POWER($B$14,$M35-3)))) -> 0.033651355 | AE35: =ROUND(D35*INDEX($N$19:$N$54,1),0) -> 2343 | AF35: =ROUND(D35*INDEX($N$19:$N$54,2),0) -> 586 | AG35: =ROUND(D35*INDEX($N$19:$N$54,3),0) -> 281 | AH35: =ROUND(D35*INDEX($N$19:$N$54,4),0) -> 117 | AI35: =ROUND(D35*INDEX($N$19:$N$54,5),0) -> 114 | AJ35: =ROUND(D35*INDEX($N$19:$N$54,6),0) -> 110 | AK35: =ROUND(D35*INDEX($N$19:$N$54,7),0) -> 107 | AL35: =ROUND(D35*INDEX($N$19:$N$54,8),0) -> 104 | AM35: =ROUND(D35*INDEX($N$19:$N$54,9),0) -> 101 | AN35: =ROUND(D35*INDEX($N$19:$N$54,10),0) -> 98 | AO35: =ROUND(D35*INDEX($N$19:$N$54,11),0) -> 95 | AP35: =ROUND(D35*INDEX($N$19:$N$54,12),0) -> 92 | AQ35: =ROUND(D35*INDEX($N$19:$N$54,13),0) -> 89 | AR35: =ROUND(D35*INDEX($N$19:$N$54,14),0) -> 86 | AS35: =ROUND(D35*INDEX($N$19:$N$54,15),0) -> 84 | AT35: =ROUND(D35*INDEX($N$19:$N$54,16),0) -> 81 | AU35: =ROUND(D35*INDEX($N$19:$N$54,17),0) -> 79 | AV35: =ROUND(D35*INDEX($N$19:$N$54,18),0) -> 76 | AW35: =ROUND(D35*INDEX($N$19:$N$54,19),0) -> 74 | AX35: =ROUND(D35*INDEX($N$19:$N$54,20),0) -> 72
A36: 2027-08-01 | B36: 2 | C36: phase_2_marketplace_activation | D36: =ROUND(MAX(100,I36*J36*K36),0) -> 2381 | E36: =MAX(0,F36-D36) -> 1815 | F36: =ROUND(SUM($AF$19:$AF$54),0) -> 4196 | H36: =IF($B36=1,$B$6,IF($B36=2,$B$7,$B$8)) -> 0.05 | I36: =I35*(1+H36) -> 2676.41 | J36: 0.921643 | K36: =MAX(0.85,1+_xlfn.NORM.INV(RAND(),0,$B$15*0.35)) -> 0.965328 | M36: 17 | N36: =IF($M36=0,1,IF($M36=1,$B$11,IF($M36=2,$B$12,IF($M36=3,$B$13,$B$13*POWER($B$14,$M36-3)))) -> 0.032641814 | AF36: =ROUND(D36*INDEX($N$19:$N$54,1),0) -> 2381 | AG36: =ROUND(D36*INDEX($N$19:$N$54,2),0) -> 595 | AH36: =ROUND(D36*INDEX($N$19:$N$54,3),0) -> 286 | AI36: =ROUND(D36*INDEX($N$19:$N$54,4),0) -> 119 | AJ36: =ROUND(D36*INDEX($N$19:$N$54,5),0) -> 115 | AK36: =ROUND(D36*INDEX($N$19:$N$54,6),0) -> 112 | AL36: =ROUND(D36*INDEX($N$19:$N$54,7),0) -> 109 | AM36: =ROUND(D36*INDEX($N$19:$N$54,8),0) -> 105 | AN36: =ROUND(D36*INDEX($N$19:$N$54,9),0) -> 102 | AO36: =ROUND(D36*INDEX($N$19:$N$54,10),0) -> 99 | AP36: =ROUND(D36*INDEX($N$19:$N$54,11),0) -> 96 | AQ36: =ROUND(D36*INDEX($N$19:$N$54,12),0) -> 93 | AR36: =ROUND(D36*INDEX($N$19:$N$54,13),0) -> 91 | AS36: =ROUND(D36*INDEX($N$19:$N$54,14),0) -> 88 | AT36: =ROUND(D36*INDEX($N$19:$N$54,15),0) -> 85 | AU36: =ROUND(D36*INDEX($N$19:$N$54,16),0) -> 83 | AV36: =ROUND(D36*INDEX($N$19:$N$54,17),0) -> 80 | AW36: =ROUND(D36*INDEX($N$19:$N$54,18),0) -> 78 | AX36: =ROUND(D36*INDEX($N$19:$N$54,19),0) -> 75
A37: 2027-09-01 | B37: 2 | C37: phase_2_marketplace_activation | D37: =ROUND(MAX(100,I37*J37*K37),0) -> 2478 | E37: =MAX(0,F37-D37) -> 1923 | F37: =ROUND(SUM($AG$19:$AG$54),0) -> 4401 | H37: =IF($B37=1,$B$6,IF($B37=2,$B$7,$B$8)) -> 0.05 | I37: =I36*(1+H37) -> 2810.24 | J37: 0.885988 | K37: =MAX(0.85,1+_xlfn.NORM.INV(RAND(),0,$B$15*0.35)) -> 0.995076 | M37: 18 | N37: =IF($M37=0,1,IF($M37=1,$B$11,IF($M37=2,$B$12,IF($M37=3,$B$13,$B$13*POWER($B$14,$M37-3)))) -> 0.031662559 | AG37: =ROUND(D37*INDEX($N$19:$N$54,1),0) -> 2478 | AH37: =ROUND(D37*INDEX($N$19:$N$54,2),0) -> 620 | AI37: =ROUND(D37*INDEX($N$19:$N$54,3),0) -> 297 | AJ37: =ROUND(D37*INDEX($N$19:$N$54,4),0) -> 124 | AK37: =ROUND(D37*INDEX($N$19:$N$54,5),0) -> 120 | AL37: =ROUND(D37*INDEX($N$19:$N$54,6),0) -> 117 | AM37: =ROUND(D37*INDEX($N$19:$N$54,7),0) -> 113 | AN37: =ROUND(D37*INDEX($N$19:$N$54,8),0) -> 110 | AO37: =ROUND(D37*INDEX($N$19:$N$54,9),0) -> 106 | AP37: =ROUND(D37*INDEX($N$19:$N$54,10),0) -> 103 | AQ37: =ROUND(D37*INDEX($N$19:$N$54,11),0) -> 100 | AR37: =ROUND(D37*INDEX($N$19:$N$54,12),0) -> 97 | AS37: =ROUND(D37*INDEX($N$19:$N$54,13),0) -> 94 | AT37: =ROUND(D37*INDEX($N$19:$N$54,14),0) -> 91 | AU37: =ROUND(D37*INDEX($N$19:$N$54,15),0) -> 89 | AV37: =ROUND(D37*INDEX($N$19:$N$54,16),0) -> 86 | AW37: =ROUND(D37*INDEX($N$19:$N$54,17),0) -> 83 | AX37: =ROUND(D37*INDEX($N$19:$N$54,18),0) -> 81
A38: 2027-10-01 | B38: 2 | C38: phase_2_marketplace_activation | D38: =ROUND(MAX(100,I38*J38*K38),0) -> 2739 | E38: =MAX(0,F38-D38) -> 2039 | F38: =ROUND(SUM($AH$19:$AH$54),0) -> 4778 | H38: =IF($B38=1,$B$6,IF($B38=2,$B$7,$B$8)) -> 0.05 | I38: =I37*(1+H38) -> 2950.75 | J38: 0.911037 | K38: =MAX(0.85,1+_xlfn.NORM.INV(RAND(),0,$B$15*0.35)) -> 1.018879 | M38: 19 | N38: =IF($M38=0,1,IF($M38=1,$B$11,IF($M38=2,$B$12,IF($M38=3,$B$13,$B$13*POWER($B$14,$M38-3)))) -> 0.030712683 | AH38: =ROUND(D38*INDEX($N$19:$N$54,1),0) -> 2739 | AI38: =ROUND(D38*INDEX($N$19:$N$54,2),0) -> 685 | AJ38: =ROUND(D38*INDEX($N$19:$N$54,3),0) -> 329 | AK38: =ROUND(D38*INDEX($N$19:$N$54,4),0) -> 137 | AL38: =ROUND(D38*INDEX($N$19:$N$54,5),0) -> 133 | AM38: =ROUND(D38*INDEX($N$19:$N$54,6),0) -> 129 | AN38: =ROUND(D38*INDEX($N$19:$N$54,7),0) -> 125 | AO38: =ROUND(D38*INDEX($N$19:$N$54,8),0) -> 121 | AP38: =ROUND(D38*INDEX($N$19:$N$54,9),0) -> 118 | AQ38: =ROUND(D38*INDEX($N$19:$N$54,10),0) -> 114 | AR38: =ROUND(D38*INDEX($N$19:$N$54,11),0) -> 111 | AS38: =ROUND(D38*INDEX($N$19:$N$54,12),0) -> 107 | AT38: =ROUND(D38*INDEX($N$19:$N$54,13),0) -> 104 | AU38: =ROUND(D38*INDEX($N$19:$N$54,14),0) -> 101 | AV38: =ROUND(D38*INDEX($N$19:$N$54,15),0) -> 98 | AW38: =ROUND(D38*INDEX($N$19:$N$54,16),0) -> 95 | AX38: =ROUND(D38*INDEX($N$19:$N$54,17),0) -> 92
A39: 2027-11-01 | B39: 2 | C39: phase_2_marketplace_activation | D39: =ROUND(MAX(100,I39*J39*K39),0) -> 4135 | E39: =MAX(0,F39-D39) -> 2200 | F39: =ROUND(SUM($AI$19:$AI$54),0) -> 6335 | H39: =IF($B39=1,$B$6,IF($B39=2,$B$7,$B$8)) -> 0.05 | I39: =I38*(1+H39) -> 3098.28 | J39: 1.344002 | K39: =MAX(0.85,1+_xlfn.NORM.INV(RAND(),0,$B$15*0.35)) -> 0.993049 | M39: 20 | N39: =IF($M39=0,1,IF($M39=1,$B$11,IF($M39=2,$B$12,IF($M39=3,$B$13,$B$13*POWER($B$14,$M39-3)))) -> 0.029791302 | AI39: =ROUND(D39*INDEX($N$19:$N$54,1),0) -> 4135 | AJ39: =ROUND(D39*INDEX($N$19:$N$54,2),0) -> 1034 | AK39: =ROUND(D39*INDEX($N$19:$N$54,3),0) -> 496 | AL39: =ROUND(D39*INDEX($N$19:$N$54,4),0) -> 207 | AM39: =ROUND(D39*INDEX($N$19:$N$54,5),0) -> 201 | AN39: =ROUND(D39*INDEX($N$19:$N$54,6),0) -> 195 | AO39: =ROUND(D39*INDEX($N$19:$N$54,7),0) -> 189 | AP39: =ROUND(D39*INDEX($N$19:$N$54,8),0) -> 183 | AQ39: =ROUND(D39*INDEX($N$19:$N$54,9),0) -> 178 | AR39: =ROUND(D39*INDEX($N$19:$N$54,10),0) -> 172 | AS39: =ROUND(D39*INDEX($N$19:$N$54,11),0) -> 167 | AT39: =ROUND(D39*INDEX($N$19:$N$54,12),0) -> 162 | AU39: =ROUND(D39*INDEX($N$19:$N$54,13),0) -> 157 | AV39: =ROUND(D39*INDEX($N$19:$N$54,14),0) -> 152 | AW39: =ROUND(D39*INDEX($N$19:$N$54,15),0) -> 148 | AX39: =ROUND(D39*INDEX($N$19:$N$54,16),0) -> 143
